/*
*** MADE BY MITHION'S .SCHEMATIC TO JAVA CONVERTING TOOL v1.6 ***
*/

package net.minecraft.mckay1717.pvp;
import java.util.Random;
import net.minecraft.src.*;

public class AlchemistTower extends WorldGenerator
{
	
	protected int[] GetValidSpawnBlocks() {
		return new int[] {
			Block.stone.blockID,
			Block.grass.blockID,
			Block.dirt.blockID
		};
	}

	public boolean LocationIsValidSpawn(World world, int i, int j, int k){
		int distanceToAir = 0;
		int checkID = world.getBlockId(i, j, k);

		while (checkID != 0){
			distanceToAir++;
			checkID = world.getBlockId(i, j + distanceToAir, k);
		}

		if (distanceToAir > 3){
			return false;
		}
		j += distanceToAir - 1;

		int blockID = world.getBlockId(i, j, k);
		int blockIDAbove = world.getBlockId(i, j+1, k);
		int blockIDBelow = world.getBlockId(i, j-1, k);
		for (int x : GetValidSpawnBlocks()){
			if (blockIDAbove != 0){
				return false;
			}
			if (blockID == x){
				return true;
			}else if (blockID == Block.snow.blockID && blockIDBelow == x){
				return true;
			}
		}
		return false;
	}

	public AlchemistTower() { }


	public boolean generate(World world, Random rand, int i, int j, int k) {
		//check that each corner is one of the valid spawn blocks
		if(!LocationIsValidSpawn(world, i, j, k) || !LocationIsValidSpawn(world, i + 20, j, k) || !LocationIsValidSpawn(world, i + 20, j, k + 10) || !LocationIsValidSpawn(world, i, j, k + 10))
		{
			return false;
		}

		world.setBlock(i + 0, j + 0, k + 0, Block.cobblestone.blockID);
		world.setBlock(i + 0, j + 0, k + 1, Block.cobblestone.blockID);
		world.setBlock(i + 0, j + 0, k + 2, Block.cobblestone.blockID);
		world.setBlock(i + 0, j + 0, k + 3, Block.cobblestone.blockID);
		world.setBlock(i + 0, j + 0, k + 4, Block.cobblestone.blockID);
		world.setBlock(i + 0, j + 0, k + 5, Block.cobblestone.blockID);
		world.setBlock(i + 0, j + 0, k + 6, Block.cobblestone.blockID);
		world.setBlock(i + 0, j + 0, k + 7, Block.cobblestone.blockID);
		world.setBlock(i + 0, j + 0, k + 8, Block.cobblestone.blockID);
		world.setBlock(i + 0, j + 0, k + 9, Block.cobblestone.blockID);
		world.setBlock(i + 0, j + 0, k + 10, Block.cobblestone.blockID);
		world.setBlock(i + 0, j + 3, k + 1, Block.glowStone.blockID);
		world.setBlock(i + 0, j + 3, k + 9, Block.glowStone.blockID);
		world.setBlock(i + 0, j + 4, k + 1, Block.fence.blockID);
		world.setBlock(i + 0, j + 4, k + 9, Block.fence.blockID);
		world.setBlock(i + 1, j + 0, k + 0, Block.cobblestone.blockID);
		world.setBlock(i + 1, j + 0, k + 1, Block.cobblestone.blockID);
		world.setBlock(i + 1, j + 0, k + 2, Block.cobblestone.blockID);
		world.setBlock(i + 1, j + 0, k + 3, Block.cobblestone.blockID);
		world.setBlock(i + 1, j + 0, k + 4, Block.cobblestone.blockID);
		world.setBlock(i + 1, j + 0, k + 5, Block.cobblestone.blockID);
		world.setBlock(i + 1, j + 0, k + 6, Block.cobblestone.blockID);
		world.setBlock(i + 1, j + 0, k + 7, Block.cobblestone.blockID);
		world.setBlock(i + 1, j + 0, k + 8, Block.cobblestone.blockID);
		world.setBlock(i + 1, j + 0, k + 9, Block.cobblestone.blockID);
		world.setBlock(i + 1, j + 0, k + 10, Block.cobblestone.blockID);
		world.setBlock(i + 1, j + 1, k + 1, Block.fence.blockID);
		world.setBlock(i + 1, j + 1, k + 9, Block.fence.blockID);
		world.setBlock(i + 1, j + 2, k + 1, Block.fence.blockID);
		world.setBlock(i + 1, j + 2, k + 9, Block.fence.blockID);
		world.setBlock(i + 1, j + 3, k + 1, Block.fence.blockID);
		world.setBlock(i + 1, j + 3, k + 9, Block.fence.blockID);
		world.setBlock(i + 1, j + 4, k + 1, Block.fence.blockID);
		world.setBlock(i + 1, j + 4, k + 9, Block.fence.blockID);
		world.setBlock(i + 2, j + 0, k + 0, Block.cobblestone.blockID);
		world.setBlock(i + 2, j + 0, k + 1, Block.cobblestone.blockID);
		world.setBlock(i + 2, j + 0, k + 2, Block.cobblestone.blockID);
		world.setBlock(i + 2, j + 0, k + 3, Block.cobblestone.blockID);
		world.setBlock(i + 2, j + 0, k + 4, Block.cobblestone.blockID);
		world.setBlockAndMetadata(i + 2, j + 0, k + 5, Block.stoneBrick.blockID, 2);
		world.setBlock(i + 2, j + 0, k + 6, Block.cobblestone.blockID);
		world.setBlock(i + 2, j + 0, k + 7, Block.cobblestone.blockID);
		world.setBlock(i + 2, j + 0, k + 8, Block.cobblestone.blockID);
		world.setBlock(i + 2, j + 0, k + 9, Block.cobblestone.blockID);
		world.setBlock(i + 2, j + 0, k + 10, Block.cobblestone.blockID);
		world.setBlock(i + 2, j + 1, k + 1, Block.fence.blockID);
		world.setBlock(i + 2, j + 1, k + 9, Block.fence.blockID);
		world.setBlock(i + 3, j + 0, k + 0, Block.cobblestone.blockID);
		world.setBlock(i + 3, j + 0, k + 1, Block.cobblestone.blockID);
		world.setBlock(i + 3, j + 0, k + 2, Block.cobblestone.blockID);
		world.setBlock(i + 3, j + 0, k + 3, Block.cobblestone.blockID);
		world.setBlock(i + 3, j + 0, k + 4, Block.cobblestone.blockID);
		world.setBlock(i + 3, j + 0, k + 5, Block.cobblestone.blockID);
		world.setBlock(i + 3, j + 0, k + 6, Block.cobblestone.blockID);
		world.setBlock(i + 3, j + 0, k + 7, Block.cobblestone.blockID);
		world.setBlock(i + 3, j + 0, k + 8, Block.cobblestone.blockID);
		world.setBlock(i + 3, j + 0, k + 9, Block.cobblestone.blockID);
		world.setBlock(i + 3, j + 0, k + 10, Block.cobblestone.blockID);
		world.setBlock(i + 3, j + 1, k + 1, Block.fence.blockID);
		world.setBlock(i + 3, j + 1, k + 2, Block.fence.blockID);
		world.setBlock(i + 3, j + 1, k + 3, Block.fence.blockID);
		world.setBlock(i + 3, j + 1, k + 7, Block.fence.blockID);
		world.setBlock(i + 3, j + 1, k + 8, Block.fence.blockID);
		world.setBlock(i + 3, j + 1, k + 9, Block.fence.blockID);
		world.setBlock(i + 4, j + 0, k + 0, Block.cobblestone.blockID);
		world.setBlock(i + 4, j + 0, k + 1, Block.cobblestone.blockID);
		world.setBlock(i + 4, j + 0, k + 2, Block.cobblestone.blockID);
		world.setBlock(i + 4, j + 0, k + 3, Block.cobblestone.blockID);
		world.setBlock(i + 4, j + 0, k + 4, Block.cobblestone.blockID);
		world.setBlockAndMetadata(i + 4, j + 0, k + 5, Block.stoneBrick.blockID, 2);
		world.setBlock(i + 4, j + 0, k + 6, Block.cobblestone.blockID);
		world.setBlock(i + 4, j + 0, k + 7, Block.cobblestone.blockID);
		world.setBlock(i + 4, j + 0, k + 8, Block.cobblestone.blockID);
		world.setBlock(i + 4, j + 0, k + 9, Block.cobblestone.blockID);
		world.setBlock(i + 4, j + 0, k + 10, Block.cobblestone.blockID);
		world.setBlock(i + 4, j + 1, k + 3, Block.fence.blockID);
		world.setBlock(i + 4, j + 1, k + 7, Block.fence.blockID);
		world.setBlock(i + 5, j + 0, k + 0, Block.cobblestone.blockID);
		world.setBlock(i + 5, j + 0, k + 1, Block.cobblestone.blockID);
		world.setBlock(i + 5, j + 0, k + 2, Block.cobblestone.blockID);
		world.setBlock(i + 5, j + 0, k + 3, Block.cobblestone.blockID);
		world.setBlock(i + 5, j + 0, k + 4, Block.cobblestone.blockID);
		world.setBlock(i + 5, j + 0, k + 5, Block.cobblestone.blockID);
		world.setBlock(i + 5, j + 0, k + 6, Block.cobblestone.blockID);
		world.setBlock(i + 5, j + 0, k + 7, Block.cobblestone.blockID);
		world.setBlock(i + 5, j + 0, k + 8, Block.cobblestone.blockID);
		world.setBlock(i + 5, j + 0, k + 9, Block.cobblestone.blockID);
		world.setBlock(i + 5, j + 0, k + 10, Block.cobblestone.blockID);
		world.setBlock(i + 5, j + 1, k + 3, Block.fence.blockID);
		world.setBlock(i + 5, j + 1, k + 7, Block.fence.blockID);
		world.setBlockAndMetadata(i + 5, j + 3, k + 2, Block.stairCompactPlanks.blockID, 2);
		world.setBlockAndMetadata(i + 5, j + 3, k + 8, Block.stairCompactPlanks.blockID, 3);
		world.setBlockAndMetadata(i + 5, j + 4, k + 3, Block.stairCompactPlanks.blockID, 2);
		world.setBlockAndMetadata(i + 5, j + 4, k + 7, Block.stairCompactPlanks.blockID, 3);
		world.setBlockAndMetadata(i + 5, j + 5, k + 4, Block.stoneSingleSlab.blockID, 2);
		world.setBlock(i + 5, j + 5, k + 5, Block.planks.blockID);
		world.setBlockAndMetadata(i + 5, j + 5, k + 6, Block.stoneSingleSlab.blockID, 2);
		world.setBlockAndMetadata(i + 5, j + 6, k + 4, Block.stairCompactPlanks.blockID, 3);
		world.setBlockAndMetadata(i + 5, j + 6, k + 5, Block.stoneSingleSlab.blockID, 2);
		world.setBlockAndMetadata(i + 5, j + 6, k + 6, Block.stairCompactPlanks.blockID, 2);
		world.setBlock(i + 6, j + 0, k + 0, Block.cobblestone.blockID);
		world.setBlock(i + 6, j + 0, k + 1, Block.cobblestone.blockID);
		world.setBlock(i + 6, j + 0, k + 2, Block.cobblestone.blockID);
		world.setBlock(i + 6, j + 0, k + 3, Block.cobblestone.blockID);
		world.setBlockAndMetadata(i + 6, j + 0, k + 4, Block.stoneBrick.blockID, 2);
		world.setBlock(i + 6, j + 0, k + 5, Block.cobblestone.blockID);
		world.setBlockAndMetadata(i + 6, j + 0, k + 6, Block.stoneBrick.blockID, 2);
		world.setBlock(i + 6, j + 0, k + 7, Block.cobblestone.blockID);
		world.setBlock(i + 6, j + 0, k + 8, Block.cobblestone.blockID);
		world.setBlock(i + 6, j + 0, k + 9, Block.cobblestone.blockID);
		world.setBlock(i + 6, j + 0, k + 10, Block.cobblestone.blockID);
		world.setBlockAndMetadata(i + 6, j + 1, k + 3, Block.stoneBrick.blockID, 2);
		world.setBlockAndMetadata(i + 6, j + 1, k + 4, Block.stairCompactPlanks.blockID, 1);
		world.setBlockAndMetadata(i + 6, j + 1, k + 6, Block.stairCompactPlanks.blockID, 1);
		world.setBlockAndMetadata(i + 6, j + 1, k + 7, Block.stoneBrick.blockID, 2);
		world.setBlock(i + 6, j + 2, k + 3, Block.stoneBrick.blockID);
		world.setBlockAndMetadata(i + 6, j + 2, k + 4, Block.stairCompactPlanks.blockID, 1);
		world.setBlockAndMetadata(i + 6, j + 2, k + 6, Block.stairCompactPlanks.blockID, 1);
		world.setBlockAndMetadata(i + 6, j + 2, k + 7, Block.stoneBrick.blockID, 2);
		world.setBlockAndMetadata(i + 6, j + 3, k + 2, Block.stairCompactPlanks.blockID, 2);
		world.setBlockAndMetadata(i + 6, j + 3, k + 3, Block.stoneBrick.blockID, 2);
		world.setBlockAndMetadata(i + 6, j + 3, k + 4, Block.stairCompactPlanks.blockID, 1);
		world.setBlockAndMetadata(i + 6, j + 3, k + 5, Block.stoneSingleSlab.blockID, 2);
		world.setBlockAndMetadata(i + 6, j + 3, k + 6, Block.stairCompactPlanks.blockID, 1);
		world.setBlock(i + 6, j + 3, k + 7, Block.stoneBrick.blockID);
		world.setBlockAndMetadata(i + 6, j + 3, k + 8, Block.stairCompactPlanks.blockID, 3);
		world.setBlockAndMetadata(i + 6, j + 4, k + 3, Block.stairCompactPlanks.blockID, 2);
		world.setBlockAndMetadata(i + 6, j + 4, k + 4, Block.stairCompactPlanks.blockID, 1);
		world.setBlockAndMetadata(i + 6, j + 4, k + 5, Block.stoneSingleSlab.blockID, 2);
		world.setBlockAndMetadata(i + 6, j + 4, k + 6, Block.stairCompactPlanks.blockID, 1);
		world.setBlockAndMetadata(i + 6, j + 4, k + 7, Block.stairCompactPlanks.blockID, 3);
		world.setBlockAndMetadata(i + 6, j + 5, k + 4, Block.stoneSingleSlab.blockID, 2);
		world.setBlockAndMetadata(i + 6, j + 5, k + 5, Block.stoneSingleSlab.blockID, 2);
		world.setBlockAndMetadata(i + 6, j + 5, k + 6, Block.stoneSingleSlab.blockID, 2);
		world.setBlock(i + 7, j + 0, k + 0, Block.cobblestone.blockID);
		world.setBlock(i + 7, j + 0, k + 1, Block.cobblestone.blockID);
		world.setBlock(i + 7, j + 0, k + 2, Block.cobblestone.blockID);
		world.setBlock(i + 7, j + 0, k + 3, Block.cobblestone.blockID);
		world.setBlock(i + 7, j + 0, k + 4, Block.cobblestone.blockID);
		world.setBlockAndMetadata(i + 7, j + 0, k + 5, Block.stoneBrick.blockID, 2);
		world.setBlockAndMetadata(i + 7, j + 0, k + 6, Block.stoneBrick.blockID, 2);
		world.setBlock(i + 7, j + 0, k + 7, Block.cobblestone.blockID);
		world.setBlock(i + 7, j + 0, k + 8, Block.cobblestone.blockID);
		world.setBlock(i + 7, j + 0, k + 9, Block.cobblestone.blockID);
		world.setBlock(i + 7, j + 0, k + 10, Block.cobblestone.blockID);
		world.setBlock(i + 7, j + 1, k + 3, Block.cobblestone.blockID);
		world.setBlock(i + 7, j + 1, k + 4, Block.stairCompactPlanks.blockID);
		world.setBlock(i + 7, j + 1, k + 6, Block.stairCompactPlanks.blockID);
		world.setBlockAndMetadata(i + 7, j + 1, k + 7, Block.stoneBrick.blockID, 2);
		world.setBlock(i + 7, j + 2, k + 3, Block.cobblestone.blockID);
		world.setBlock(i + 7, j + 2, k + 4, Block.stairCompactPlanks.blockID);
		world.setBlock(i + 7, j + 2, k + 6, Block.stairCompactPlanks.blockID);
		world.setBlockAndMetadata(i + 7, j + 2, k + 7, Block.stoneBrick.blockID, 2);
		world.setBlockAndMetadata(i + 7, j + 3, k + 2, Block.stairCompactPlanks.blockID, 2);
		world.setBlock(i + 7, j + 3, k + 3, Block.cobblestone.blockID);
		world.setBlock(i + 7, j + 3, k + 4, Block.stairCompactPlanks.blockID);
		world.setBlockAndMetadata(i + 7, j + 3, k + 5, Block.stoneSingleSlab.blockID, 2);
		world.setBlock(i + 7, j + 3, k + 6, Block.stairCompactPlanks.blockID);
		world.setBlockAndMetadata(i + 7, j + 3, k + 7, Block.stoneBrick.blockID, 2);
		world.setBlockAndMetadata(i + 7, j + 3, k + 8, Block.stairCompactPlanks.blockID, 3);
		world.setBlockAndMetadata(i + 7, j + 4, k + 3, Block.stairCompactPlanks.blockID, 2);
		world.setBlock(i + 7, j + 4, k + 4, Block.stairCompactPlanks.blockID);
		world.setBlockAndMetadata(i + 7, j + 4, k + 5, Block.stoneSingleSlab.blockID, 2);
		world.setBlock(i + 7, j + 4, k + 6, Block.stairCompactPlanks.blockID);
		world.setBlockAndMetadata(i + 7, j + 4, k + 7, Block.stairCompactPlanks.blockID, 3);
		world.setBlockAndMetadata(i + 7, j + 5, k + 4, Block.stoneSingleSlab.blockID, 2);
		world.setBlockAndMetadata(i + 7, j + 5, k + 5, Block.stoneSingleSlab.blockID, 2);
		world.setBlockAndMetadata(i + 7, j + 5, k + 6, Block.stoneSingleSlab.blockID, 2);
		world.setBlock(i + 8, j + 0, k + 0, Block.cobblestone.blockID);
		world.setBlock(i + 8, j + 0, k + 1, Block.cobblestone.blockID);
		world.setBlock(i + 8, j + 0, k + 2, Block.cobblestone.blockID);
		world.setBlock(i + 8, j + 0, k + 3, Block.cobblestone.blockID);
		world.setBlock(i + 8, j + 0, k + 4, Block.cobblestone.blockID);
		world.setBlockAndMetadata(i + 8, j + 0, k + 5, Block.stoneBrick.blockID, 2);
		world.setBlock(i + 8, j + 0, k + 6, Block.cobblestone.blockID);
		world.setBlock(i + 8, j + 0, k + 7, Block.cobblestone.blockID);
		world.setBlock(i + 8, j + 0, k + 8, Block.cobblestone.blockID);
		world.setBlock(i + 8, j + 0, k + 9, Block.cobblestone.blockID);
		world.setBlock(i + 8, j + 0, k + 10, Block.cobblestone.blockID);
		world.setBlock(i + 8, j + 1, k + 3, Block.stoneBrick.blockID);
		world.setBlock(i + 8, j + 1, k + 4, Block.stairCompactPlanks.blockID);
		world.setBlock(i + 8, j + 1, k + 6, Block.stairCompactPlanks.blockID);
		world.setBlock(i + 8, j + 1, k + 7, Block.stoneBrick.blockID);
		world.setBlock(i + 8, j + 2, k + 3, Block.stoneBrick.blockID);
		world.setBlock(i + 8, j + 2, k + 4, Block.stairCompactPlanks.blockID);
		world.setBlock(i + 8, j + 2, k + 6, Block.stairCompactPlanks.blockID);
		world.setBlock(i + 8, j + 2, k + 7, Block.stoneBrick.blockID);
		world.setBlockAndMetadata(i + 8, j + 3, k + 2, Block.stairCompactPlanks.blockID, 2);
		world.setBlockAndMetadata(i + 8, j + 3, k + 3, Block.stoneBrick.blockID, 2);
		world.setBlock(i + 8, j + 3, k + 4, Block.stairCompactPlanks.blockID);
		world.setBlockAndMetadata(i + 8, j + 3, k + 5, Block.stoneSingleSlab.blockID, 2);
		world.setBlock(i + 8, j + 3, k + 6, Block.stairCompactPlanks.blockID);
		world.setBlockAndMetadata(i + 8, j + 3, k + 7, Block.stoneBrick.blockID, 2);
		world.setBlockAndMetadata(i + 8, j + 3, k + 8, Block.stairCompactPlanks.blockID, 3);
		world.setBlockAndMetadata(i + 8, j + 4, k + 3, Block.stairCompactPlanks.blockID, 2);
		world.setBlock(i + 8, j + 4, k + 4, Block.stairCompactPlanks.blockID);
		world.setBlockAndMetadata(i + 8, j + 4, k + 5, Block.stoneSingleSlab.blockID, 2);
		world.setBlock(i + 8, j + 4, k + 6, Block.stairCompactPlanks.blockID);
		world.setBlockAndMetadata(i + 8, j + 4, k + 7, Block.stairCompactPlanks.blockID, 3);
		world.setBlockAndMetadata(i + 8, j + 5, k + 4, Block.stoneSingleSlab.blockID, 2);
		world.setBlockAndMetadata(i + 8, j + 5, k + 5, Block.stoneSingleSlab.blockID, 2);
		world.setBlockAndMetadata(i + 8, j + 5, k + 6, Block.stoneSingleSlab.blockID, 2);
		world.setBlock(i + 9, j + 0, k + 0, Block.cobblestone.blockID);
		world.setBlock(i + 9, j + 0, k + 1, Block.cobblestone.blockID);
		world.setBlock(i + 9, j + 0, k + 2, Block.cobblestone.blockID);
		world.setBlock(i + 9, j + 0, k + 3, Block.cobblestone.blockID);
		world.setBlock(i + 9, j + 0, k + 4, Block.cobblestone.blockID);
		world.setBlock(i + 9, j + 0, k + 5, Block.cobblestone.blockID);
		world.setBlock(i + 9, j + 0, k + 6, Block.cobblestone.blockID);
		world.setBlock(i + 9, j + 0, k + 7, Block.cobblestone.blockID);
		world.setBlock(i + 9, j + 0, k + 8, Block.cobblestone.blockID);
		world.setBlock(i + 9, j + 0, k + 9, Block.cobblestone.blockID);
		world.setBlock(i + 9, j + 0, k + 10, Block.cobblestone.blockID);
		world.setBlock(i + 9, j + 1, k + 3, Block.stoneBrick.blockID);
		world.setBlock(i + 9, j + 1, k + 4, Block.stairCompactPlanks.blockID);
		world.setBlock(i + 9, j + 1, k + 6, Block.stairCompactPlanks.blockID);
		world.setBlock(i + 9, j + 1, k + 7, Block.stoneBrick.blockID);
		world.setBlock(i + 9, j + 2, k + 3, Block.stoneBrick.blockID);
		world.setBlock(i + 9, j + 2, k + 4, Block.stairCompactPlanks.blockID);
		world.setBlock(i + 9, j + 2, k + 6, Block.stairCompactPlanks.blockID);
		world.setBlock(i + 9, j + 2, k + 7, Block.stoneBrick.blockID);
		world.setBlockAndMetadata(i + 9, j + 3, k + 2, Block.stairCompactPlanks.blockID, 2);
		world.setBlock(i + 9, j + 3, k + 3, Block.stoneBrick.blockID);
		world.setBlock(i + 9, j + 3, k + 4, Block.stairCompactPlanks.blockID);
		world.setBlockAndMetadata(i + 9, j + 3, k + 5, Block.stoneSingleSlab.blockID, 2);
		world.setBlock(i + 9, j + 3, k + 6, Block.stairCompactPlanks.blockID);
		world.setBlock(i + 9, j + 3, k + 7, Block.stoneBrick.blockID);
		world.setBlockAndMetadata(i + 9, j + 3, k + 8, Block.stairCompactPlanks.blockID, 3);
		world.setBlockAndMetadata(i + 9, j + 4, k + 3, Block.stairCompactPlanks.blockID, 2);
		world.setBlock(i + 9, j + 4, k + 4, Block.stairCompactPlanks.blockID);
		world.setBlockAndMetadata(i + 9, j + 4, k + 5, Block.stoneSingleSlab.blockID, 2);
		world.setBlock(i + 9, j + 4, k + 6, Block.stairCompactPlanks.blockID);
		world.setBlockAndMetadata(i + 9, j + 4, k + 7, Block.stairCompactPlanks.blockID, 3);
		world.setBlockAndMetadata(i + 9, j + 5, k + 4, Block.stoneSingleSlab.blockID, 2);
		world.setBlockAndMetadata(i + 9, j + 5, k + 5, Block.stoneSingleSlab.blockID, 2);
		world.setBlockAndMetadata(i + 9, j + 5, k + 6, Block.stoneSingleSlab.blockID, 2);
		world.setBlock(i + 10, j + 0, k + 0, Block.cobblestone.blockID);
		world.setBlock(i + 10, j + 0, k + 1, Block.cobblestone.blockID);
		world.setBlock(i + 10, j + 0, k + 2, Block.cobblestone.blockID);
		world.setBlock(i + 10, j + 0, k + 3, Block.cobblestone.blockID);
		world.setBlock(i + 10, j + 0, k + 4, Block.cobblestone.blockID);
		world.setBlock(i + 10, j + 0, k + 5, Block.cobblestone.blockID);
		world.setBlock(i + 10, j + 0, k + 6, Block.cobblestone.blockID);
		world.setBlock(i + 10, j + 0, k + 7, Block.cobblestone.blockID);
		world.setBlock(i + 10, j + 0, k + 8, Block.cobblestone.blockID);
		world.setBlock(i + 10, j + 0, k + 9, Block.cobblestone.blockID);
		world.setBlock(i + 10, j + 0, k + 10, Block.cobblestone.blockID);
		world.setBlockAndMetadata(i + 10, j + 1, k + 3, Block.stoneBrick.blockID, 2);
		world.setBlock(i + 10, j + 1, k + 4, Block.stairCompactPlanks.blockID);
		world.setBlock(i + 10, j + 1, k + 6, Block.stairCompactPlanks.blockID);
		world.setBlock(i + 10, j + 1, k + 7, Block.cobblestone.blockID);
		world.setBlock(i + 10, j + 2, k + 3, Block.cobblestone.blockID);
		world.setBlock(i + 10, j + 2, k + 4, Block.stairCompactPlanks.blockID);
		world.setBlock(i + 10, j + 2, k + 6, Block.stairCompactPlanks.blockID);
		world.setBlock(i + 10, j + 2, k + 7, Block.cobblestone.blockID);
		world.setBlockAndMetadata(i + 10, j + 3, k + 2, Block.stairCompactPlanks.blockID, 2);
		world.setBlock(i + 10, j + 3, k + 3, Block.cobblestone.blockID);
		world.setBlock(i + 10, j + 3, k + 4, Block.stairCompactPlanks.blockID);
		world.setBlockAndMetadata(i + 10, j + 3, k + 5, Block.stoneSingleSlab.blockID, 2);
		world.setBlock(i + 10, j + 3, k + 6, Block.stairCompactPlanks.blockID);
		world.setBlock(i + 10, j + 3, k + 7, Block.cobblestone.blockID);
		world.setBlockAndMetadata(i + 10, j + 3, k + 8, Block.stairCompactPlanks.blockID, 3);
		world.setBlock(i + 10, j + 4, k + 3, Block.planks.blockID);
		world.setBlock(i + 10, j + 4, k + 4, Block.stairCompactPlanks.blockID);
		world.setBlockAndMetadata(i + 10, j + 4, k + 5, Block.stoneSingleSlab.blockID, 2);
		world.setBlock(i + 10, j + 4, k + 6, Block.stairCompactPlanks.blockID);
		world.setBlock(i + 10, j + 4, k + 7, Block.planks.blockID);
		world.setBlock(i + 10, j + 5, k + 3, Block.stairCompactCobblestone.blockID);
		world.setBlockAndMetadata(i + 10, j + 5, k + 4, Block.stoneSingleSlab.blockID, 2);
		world.setBlockAndMetadata(i + 10, j + 5, k + 5, Block.stoneSingleSlab.blockID, 2);
		world.setBlockAndMetadata(i + 10, j + 5, k + 6, Block.stoneSingleSlab.blockID, 2);
		world.setBlock(i + 10, j + 5, k + 7, Block.stairCompactCobblestone.blockID);
		world.setBlock(i + 10, j + 6, k + 3, Block.stairCompactCobblestone.blockID);
		world.setBlock(i + 10, j + 6, k + 7, Block.stairCompactCobblestone.blockID);
		world.setBlock(i + 10, j + 7, k + 3, Block.stairCompactCobblestone.blockID);
		world.setBlock(i + 10, j + 7, k + 7, Block.stairCompactCobblestone.blockID);
		world.setBlock(i + 10, j + 16, k + 4, Block.glass.blockID);
		world.setBlock(i + 10, j + 16, k + 5, Block.blockSteel.blockID);
		world.setBlock(i + 10, j + 16, k + 6, Block.glass.blockID);
		world.setBlock(i + 10, j + 17, k + 3, Block.glass.blockID);
		world.setBlock(i + 10, j + 17, k + 4, Block.glass.blockID);
		world.setBlock(i + 10, j + 17, k + 5, Block.blockSteel.blockID);
		world.setBlock(i + 10, j + 17, k + 6, Block.glass.blockID);
		world.setBlock(i + 10, j + 17, k + 7, Block.glass.blockID);
		world.setBlock(i + 10, j + 18, k + 3, Block.blockSteel.blockID);
		world.setBlock(i + 10, j + 18, k + 4, Block.blockSteel.blockID);
		world.setBlock(i + 10, j + 18, k + 5, Block.blockSteel.blockID);
		world.setBlock(i + 10, j + 18, k + 6, Block.blockSteel.blockID);
		world.setBlock(i + 10, j + 18, k + 7, Block.blockSteel.blockID);
		world.setBlock(i + 10, j + 19, k + 3, Block.glass.blockID);
		world.setBlock(i + 10, j + 19, k + 4, Block.glass.blockID);
		world.setBlock(i + 10, j + 19, k + 5, Block.blockSteel.blockID);
		world.setBlock(i + 10, j + 19, k + 6, Block.glass.blockID);
		world.setBlock(i + 10, j + 19, k + 7, Block.glass.blockID);
		world.setBlock(i + 10, j + 20, k + 4, Block.glass.blockID);
		world.setBlock(i + 10, j + 20, k + 5, Block.blockSteel.blockID);
		world.setBlock(i + 10, j + 20, k + 6, Block.glass.blockID);
		world.setBlock(i + 10, j + 21, k + 5, Block.stairCompactPlanks.blockID);
		world.setBlock(i + 11, j + 0, k + 0, Block.cobblestone.blockID);
		world.setBlock(i + 11, j + 0, k + 1, Block.cobblestone.blockID);
		world.setBlock(i + 11, j + 0, k + 2, Block.cobblestone.blockID);
		world.setBlock(i + 11, j + 0, k + 3, Block.cobblestone.blockID);
		world.setBlock(i + 11, j + 0, k + 4, Block.cobblestone.blockID);
		world.setBlock(i + 11, j + 0, k + 5, Block.cobblestone.blockID);
		world.setBlock(i + 11, j + 0, k + 6, Block.cobblestone.blockID);
		world.setBlock(i + 11, j + 0, k + 7, Block.cobblestone.blockID);
		world.setBlock(i + 11, j + 0, k + 8, Block.cobblestone.blockID);
		world.setBlock(i + 11, j + 0, k + 9, Block.cobblestone.blockID);
		world.setBlock(i + 11, j + 0, k + 10, Block.cobblestone.blockID);
		world.setBlock(i + 11, j + 1, k + 2, Block.stoneBrick.blockID);
		world.setBlock(i + 11, j + 1, k + 3, Block.stoneBrick.blockID);
		world.setBlock(i + 11, j + 1, k + 4, Block.fence.blockID);
		world.setBlock(i + 11, j + 1, k + 6, Block.fence.blockID);
		world.setBlock(i + 11, j + 1, k + 7, Block.stoneBrick.blockID);
		world.setBlockAndMetadata(i + 11, j + 1, k + 8, Block.stoneBrick.blockID, 2);
		world.setBlock(i + 11, j + 2, k + 3, Block.stoneBrick.blockID);
		world.setBlock(i + 11, j + 2, k + 4, Block.fence.blockID);
		world.setBlock(i + 11, j + 2, k + 6, Block.fence.blockID);
		world.setBlock(i + 11, j + 2, k + 7, Block.stoneBrick.blockID);
		world.setBlockAndMetadata(i + 11, j + 3, k + 2, Block.stairCompactPlanks.blockID, 2);
		world.setBlock(i + 11, j + 3, k + 3, Block.stoneBrick.blockID);
		world.setBlockAndMetadata(i + 11, j + 3, k + 4, Block.stairCompactPlanks.blockID, 3);
		world.setBlockAndMetadata(i + 11, j + 3, k + 5, Block.stoneSingleSlab.blockID, 2);
		world.setBlockAndMetadata(i + 11, j + 3, k + 6, Block.stairCompactPlanks.blockID, 2);
		world.setBlock(i + 11, j + 3, k + 7, Block.stoneBrick.blockID);
		world.setBlockAndMetadata(i + 11, j + 3, k + 8, Block.stairCompactPlanks.blockID, 3);
		world.setBlock(i + 11, j + 4, k + 3, Block.stoneBrick.blockID);
		world.setBlockAndMetadata(i + 11, j + 4, k + 4, Block.stairCompactPlanks.blockID, 3);
		world.setBlockAndMetadata(i + 11, j + 4, k + 5, Block.stoneSingleSlab.blockID, 2);
		world.setBlockAndMetadata(i + 11, j + 4, k + 6, Block.stairCompactPlanks.blockID, 2);
		world.setBlock(i + 11, j + 4, k + 7, Block.stoneBrick.blockID);
		world.setBlock(i + 11, j + 5, k + 3, Block.stoneBrick.blockID);
		world.setBlockAndMetadata(i + 11, j + 5, k + 4, Block.stairCompactPlanks.blockID, 3);
		world.setBlockAndMetadata(i + 11, j + 5, k + 5, Block.stoneSingleSlab.blockID, 2);
		world.setBlockAndMetadata(i + 11, j + 5, k + 6, Block.stairCompactPlanks.blockID, 2);
		world.setBlock(i + 11, j + 5, k + 7, Block.stoneBrick.blockID);
		world.setBlock(i + 11, j + 6, k + 3, Block.stoneBrick.blockID);
		world.setBlockAndMetadata(i + 11, j + 6, k + 4, Block.stairCompactPlanks.blockID, 3);
		world.setBlockAndMetadata(i + 11, j + 6, k + 5, Block.stoneSingleSlab.blockID, 2);
		world.setBlockAndMetadata(i + 11, j + 6, k + 6, Block.stairCompactPlanks.blockID, 2);
		world.setBlock(i + 11, j + 6, k + 7, Block.stoneBrick.blockID);
		world.setBlock(i + 11, j + 7, k + 3, Block.stoneBrick.blockID);
		world.setBlockAndMetadata(i + 11, j + 7, k + 4, Block.stairCompactPlanks.blockID, 3);
		world.setBlockAndMetadata(i + 11, j + 7, k + 5, Block.stoneSingleSlab.blockID, 2);
		world.setBlockAndMetadata(i + 11, j + 7, k + 6, Block.stairCompactPlanks.blockID, 2);
		world.setBlock(i + 11, j + 7, k + 7, Block.cobblestone.blockID);
		world.setBlock(i + 11, j + 8, k + 3, Block.fence.blockID);
		world.setBlock(i + 11, j + 8, k + 4, Block.fence.blockID);
		world.setBlock(i + 11, j + 8, k + 5, Block.fence.blockID);
		world.setBlock(i + 11, j + 8, k + 6, Block.fence.blockID);
		world.setBlock(i + 11, j + 8, k + 7, Block.fence.blockID);
		world.setBlock(i + 11, j + 15, k + 3, Block.glass.blockID);
		world.setBlock(i + 11, j + 15, k + 4, Block.glass.blockID);
		world.setBlock(i + 11, j + 15, k + 5, Block.blockSteel.blockID);
		world.setBlock(i + 11, j + 15, k + 6, Block.glass.blockID);
		world.setBlock(i + 11, j + 15, k + 7, Block.glass.blockID);
		world.setBlock(i + 11, j + 16, k + 2, Block.glass.blockID);
		world.setBlock(i + 11, j + 16, k + 3, Block.glass.blockID);
		world.setBlock(i + 11, j + 16, k + 4, Block.glass.blockID);
		world.setBlock(i + 11, j + 16, k + 6, Block.glass.blockID);
		world.setBlock(i + 11, j + 16, k + 7, Block.glass.blockID);
		world.setBlock(i + 11, j + 16, k + 8, Block.glass.blockID);
		world.setBlock(i + 11, j + 17, k + 2, Block.glass.blockID);
		world.setBlock(i + 11, j + 17, k + 3, Block.glass.blockID);
		world.setBlock(i + 11, j + 17, k + 4, Block.planks.blockID);
		world.setBlock(i + 11, j + 17, k + 5, Block.planks.blockID);
		world.setBlock(i + 11, j + 17, k + 6, Block.planks.blockID);
		world.setBlock(i + 11, j + 17, k + 7, Block.glass.blockID);
		world.setBlock(i + 11, j + 17, k + 8, Block.glass.blockID);
		world.setBlock(i + 11, j + 18, k + 2, Block.blockSteel.blockID);
		world.setBlock(i + 11, j + 18, k + 3, Block.bookShelf.blockID);
		world.setBlock(i + 11, j + 18, k + 4, Block.bookShelf.blockID);
		world.setBlock(i + 11, j + 18, k + 5, Block.bookShelf.blockID);
		world.setBlock(i + 11, j + 18, k + 6, Block.bookShelf.blockID);
		world.setBlock(i + 11, j + 18, k + 7, Block.bookShelf.blockID);
		world.setBlock(i + 11, j + 18, k + 8, Block.blockSteel.blockID);
		world.setBlock(i + 11, j + 19, k + 2, Block.glass.blockID);
		world.setBlock(i + 11, j + 19, k + 3, Block.glass.blockID);
		world.setBlock(i + 11, j + 19, k + 4, Block.bookShelf.blockID);
		world.setBlock(i + 11, j + 19, k + 5, Block.bookShelf.blockID);
		world.setBlock(i + 11, j + 19, k + 6, Block.bookShelf.blockID);
		world.setBlock(i + 11, j + 19, k + 7, Block.glass.blockID);
		world.setBlock(i + 11, j + 19, k + 8, Block.glass.blockID);
		world.setBlock(i + 11, j + 20, k + 2, Block.glass.blockID);
		world.setBlock(i + 11, j + 20, k + 3, Block.glass.blockID);
		world.setBlock(i + 11, j + 20, k + 4, Block.glass.blockID);
		world.setBlock(i + 11, j + 20, k + 5, Block.bookShelf.blockID);
		world.setBlock(i + 11, j + 20, k + 6, Block.glass.blockID);
		world.setBlock(i + 11, j + 20, k + 7, Block.glass.blockID);
		world.setBlock(i + 11, j + 20, k + 8, Block.glass.blockID);
		world.setBlock(i + 11, j + 21, k + 3, Block.glass.blockID);
		world.setBlock(i + 11, j + 21, k + 4, Block.glass.blockID);
		world.setBlock(i + 11, j + 21, k + 5, Block.blockSteel.blockID);
		world.setBlock(i + 11, j + 21, k + 6, Block.glass.blockID);
		world.setBlock(i + 11, j + 21, k + 7, Block.glass.blockID);
		world.setBlock(i + 11, j + 22, k + 5, Block.stairCompactPlanks.blockID);
		world.setBlock(i + 12, j + 0, k + 0, Block.cobblestone.blockID);
		world.setBlock(i + 12, j + 0, k + 1, Block.cobblestone.blockID);
		world.setBlock(i + 12, j + 0, k + 2, Block.cobblestone.blockID);
		world.setBlockAndMetadata(i + 12, j + 0, k + 3, Block.stoneBrick.blockID, 2);
		world.setBlock(i + 12, j + 0, k + 4, Block.cobblestone.blockID);
		world.setBlock(i + 12, j + 0, k + 5, Block.cobblestone.blockID);
		world.setBlock(i + 12, j + 0, k + 6, Block.cobblestone.blockID);
		world.setBlock(i + 12, j + 0, k + 7, Block.cobblestone.blockID);
		world.setBlock(i + 12, j + 0, k + 8, Block.cobblestone.blockID);
		world.setBlock(i + 12, j + 0, k + 9, Block.cobblestone.blockID);
		world.setBlock(i + 12, j + 0, k + 10, Block.cobblestone.blockID);
		world.setBlock(i + 12, j + 1, k + 1, Block.stoneBrick.blockID);
		world.setBlock(i + 12, j + 1, k + 2, Block.stoneBrick.blockID);
		world.setBlock(i + 12, j + 1, k + 8, Block.stoneBrick.blockID);
		world.setBlockAndMetadata(i + 12, j + 1, k + 9, Block.stoneBrick.blockID, 2);
		world.setBlock(i + 12, j + 2, k + 2, Block.stoneBrick.blockID);
		world.setBlock(i + 12, j + 2, k + 8, Block.stoneBrick.blockID);
		world.setBlock(i + 12, j + 3, k + 2, Block.stoneBrick.blockID);
		world.setBlock(i + 12, j + 3, k + 8, Block.stoneBrick.blockID);
		world.setBlock(i + 12, j + 4, k + 2, Block.stoneBrick.blockID);
		world.setBlock(i + 12, j + 4, k + 8, Block.stoneBrick.blockID);
		world.setBlock(i + 12, j + 5, k + 2, Block.stoneBrick.blockID);
		world.setBlock(i + 12, j + 5, k + 8, Block.stoneBrick.blockID);
		world.setBlock(i + 12, j + 6, k + 2, Block.stoneBrick.blockID);
		world.setBlock(i + 12, j + 6, k + 3, Block.glowStone.blockID);
		world.setBlock(i + 12, j + 6, k + 4, Block.bookShelf.blockID);
		world.setBlock(i + 12, j + 6, k + 5, Block.bookShelf.blockID);
		world.setBlock(i + 12, j + 6, k + 6, Block.bookShelf.blockID);
		world.setBlock(i + 12, j + 6, k + 7, Block.glowStone.blockID);
		world.setBlock(i + 12, j + 6, k + 8, Block.stoneBrick.blockID);
		world.setBlock(i + 12, j + 7, k + 2, Block.stoneBrick.blockID);
		world.setBlock(i + 12, j + 7, k + 3, Block.planks.blockID);
		world.setBlock(i + 12, j + 7, k + 4, Block.planks.blockID);
		world.setBlock(i + 12, j + 7, k + 5, Block.planks.blockID);
		world.setBlock(i + 12, j + 7, k + 6, Block.planks.blockID);
		world.setBlock(i + 12, j + 7, k + 7, Block.planks.blockID);
		world.setBlock(i + 12, j + 7, k + 8, Block.cobblestone.blockID);
		world.setBlock(i + 12, j + 8, k + 2, Block.fence.blockID);
		world.setBlock(i + 12, j + 8, k + 3, Block.fence.blockID);
		world.setBlockAndMetadata(i + 12, j + 8, k + 4, Block.wood.blockID, 1);
		world.setBlock(i + 12, j + 8, k + 5, Block.wood.blockID);
		world.setBlockAndMetadata(i + 12, j + 8, k + 6, Block.wood.blockID, 1);
		world.setBlock(i + 12, j + 8, k + 7, Block.fence.blockID);
		world.setBlock(i + 12, j + 8, k + 8, Block.fence.blockID);
		world.setBlock(i + 12, j + 9, k + 2, Block.fence.blockID);
		world.setBlock(i + 12, j + 9, k + 3, Block.fence.blockID);
		world.setBlockAndMetadata(i + 12, j + 9, k + 4, Block.wood.blockID, 1);
		world.setBlock(i + 12, j + 9, k + 5, Block.brick.blockID);
		world.setBlockAndMetadata(i + 12, j + 9, k + 6, Block.wood.blockID, 1);
		world.setBlock(i + 12, j + 9, k + 7, Block.fence.blockID);
		world.setBlock(i + 12, j + 9, k + 8, Block.fence.blockID);
		world.setBlock(i + 12, j + 10, k + 2, Block.fence.blockID);
		world.setBlock(i + 12, j + 10, k + 3, Block.fence.blockID);
		world.setBlock(i + 12, j + 10, k + 4, Block.brick.blockID);
		world.setBlock(i + 12, j + 10, k + 5, Block.brick.blockID);
		world.setBlock(i + 12, j + 10, k + 6, Block.brick.blockID);
		world.setBlock(i + 12, j + 10, k + 7, Block.fence.blockID);
		world.setBlock(i + 12, j + 10, k + 8, Block.fence.blockID);
		world.setBlock(i + 12, j + 11, k + 2, Block.fence.blockID);
		world.setBlock(i + 12, j + 11, k + 3, Block.fence.blockID);
		world.setBlockAndMetadata(i + 12, j + 11, k + 4, Block.wood.blockID, 1);
		world.setBlock(i + 12, j + 11, k + 5, Block.brick.blockID);
		world.setBlockAndMetadata(i + 12, j + 11, k + 6, Block.wood.blockID, 1);
		world.setBlock(i + 12, j + 11, k + 7, Block.fence.blockID);
		world.setBlock(i + 12, j + 11, k + 8, Block.fence.blockID);
		world.setBlock(i + 12, j + 12, k + 2, Block.fence.blockID);
		world.setBlock(i + 12, j + 12, k + 3, Block.fence.blockID);
		world.setBlockAndMetadata(i + 12, j + 12, k + 4, Block.wood.blockID, 1);
		world.setBlock(i + 12, j + 12, k + 5, Block.wood.blockID);
		world.setBlockAndMetadata(i + 12, j + 12, k + 6, Block.wood.blockID, 1);
		world.setBlock(i + 12, j + 12, k + 7, Block.fence.blockID);
		world.setBlock(i + 12, j + 12, k + 8, Block.fence.blockID);
		world.setBlock(i + 12, j + 13, k + 2, Block.fence.blockID);
		world.setBlock(i + 12, j + 13, k + 3, Block.fence.blockID);
		world.setBlock(i + 12, j + 13, k + 4, Block.stairCompactPlanks.blockID);
		world.setBlock(i + 12, j + 13, k + 5, Block.stairCompactPlanks.blockID);
		world.setBlock(i + 12, j + 13, k + 6, Block.stairCompactPlanks.blockID);
		world.setBlock(i + 12, j + 13, k + 7, Block.fence.blockID);
		world.setBlock(i + 12, j + 13, k + 8, Block.fence.blockID);
		world.setBlock(i + 12, j + 14, k + 2, Block.fence.blockID);
		world.setBlock(i + 12, j + 14, k + 3, Block.glass.blockID);
		world.setBlock(i + 12, j + 14, k + 4, Block.glass.blockID);
		world.setBlock(i + 12, j + 14, k + 5, Block.blockSteel.blockID);
		world.setBlock(i + 12, j + 14, k + 6, Block.glass.blockID);
		world.setBlock(i + 12, j + 14, k + 7, Block.glass.blockID);
		world.setBlock(i + 12, j + 14, k + 8, Block.fence.blockID);
		world.setBlock(i + 12, j + 15, k + 2, Block.glass.blockID);
		world.setBlock(i + 12, j + 15, k + 3, Block.glass.blockID);
		world.setBlock(i + 12, j + 15, k + 7, Block.glass.blockID);
		world.setBlock(i + 12, j + 15, k + 8, Block.glass.blockID);
		world.setBlock(i + 12, j + 16, k + 1, Block.glass.blockID);
		world.setBlock(i + 12, j + 16, k + 2, Block.glass.blockID);
		world.setBlock(i + 12, j + 16, k + 3, Block.blockGold.blockID);
		world.setBlock(i + 12, j + 16, k + 7, Block.blockGold.blockID);
		world.setBlock(i + 12, j + 16, k + 8, Block.glass.blockID);
		world.setBlock(i + 12, j + 16, k + 9, Block.glass.blockID);
		world.setBlock(i + 12, j + 17, k + 1, Block.glass.blockID);
		world.setBlock(i + 12, j + 17, k + 2, Block.planks.blockID);
		world.setBlock(i + 12, j + 17, k + 3, Block.planks.blockID);
		world.setBlock(i + 12, j + 17, k + 4, Block.planks.blockID);
		world.setBlock(i + 12, j + 17, k + 5, Block.planks.blockID);
		world.setBlock(i + 12, j + 17, k + 6, Block.planks.blockID);
		world.setBlock(i + 12, j + 17, k + 7, Block.planks.blockID);
		world.setBlock(i + 12, j + 17, k + 8, Block.planks.blockID);
		world.setBlock(i + 12, j + 17, k + 9, Block.glass.blockID);
		world.setBlock(i + 12, j + 18, k + 1, Block.blockSteel.blockID);
		world.setBlockAndMetadata(i + 12, j + 18, k + 2, Block.chest.blockID, 3);
		world.setBlockAndMetadata(i + 12, j + 18, k + 8, Block.chest.blockID, 2);
		world.setBlock(i + 12, j + 18, k + 9, Block.blockSteel.blockID);
		world.setBlock(i + 12, j + 19, k + 1, Block.glass.blockID);
		world.setBlock(i + 12, j + 19, k + 9, Block.glass.blockID);
		world.setBlock(i + 12, j + 20, k + 1, Block.glass.blockID);
		world.setBlock(i + 12, j + 20, k + 2, Block.glass.blockID);
		world.setBlock(i + 12, j + 20, k + 8, Block.glass.blockID);
		world.setBlock(i + 12, j + 20, k + 9, Block.glass.blockID);
		world.setBlock(i + 12, j + 21, k + 2, Block.glass.blockID);
		world.setBlock(i + 12, j + 21, k + 3, Block.glass.blockID);
		world.setBlock(i + 12, j + 21, k + 7, Block.glass.blockID);
		world.setBlock(i + 12, j + 21, k + 8, Block.glass.blockID);
		world.setBlock(i + 12, j + 22, k + 3, Block.glass.blockID);
		world.setBlock(i + 12, j + 22, k + 4, Block.glass.blockID);
		world.setBlock(i + 12, j + 22, k + 5, Block.blockSteel.blockID);
		world.setBlock(i + 12, j + 22, k + 6, Block.glass.blockID);
		world.setBlock(i + 12, j + 22, k + 7, Block.glass.blockID);
		world.setBlock(i + 12, j + 23, k + 5, Block.stairCompactPlanks.blockID);
		world.setBlock(i + 13, j + 0, k + 0, Block.cobblestone.blockID);
		world.setBlock(i + 13, j + 0, k + 1, Block.cobblestone.blockID);
		world.setBlock(i + 13, j + 0, k + 2, Block.cobblestone.blockID);
		world.setBlock(i + 13, j + 0, k + 3, Block.cobblestone.blockID);
		world.setBlock(i + 13, j + 0, k + 4, Block.cobblestone.blockID);
		world.setBlock(i + 13, j + 0, k + 5, Block.cobblestone.blockID);
		world.setBlock(i + 13, j + 0, k + 6, Block.cobblestone.blockID);
		world.setBlock(i + 13, j + 0, k + 7, Block.cobblestone.blockID);
		world.setBlock(i + 13, j + 0, k + 8, Block.cobblestone.blockID);
		world.setBlock(i + 13, j + 0, k + 9, Block.cobblestone.blockID);
		world.setBlock(i + 13, j + 0, k + 10, Block.cobblestone.blockID);
		world.setBlockAndMetadata(i + 13, j + 1, k + 0, Block.stoneBrick.blockID, 2);
		world.setBlock(i + 13, j + 1, k + 1, Block.stoneBrick.blockID);
		world.setBlockAndMetadata(i + 13, j + 1, k + 2, Block.stoneOvenActive.blockID, 3);
		world.setBlockAndMetadata(i + 13, j + 1, k + 8, Block.stoneOvenActive.blockID, 2);
		world.setBlock(i + 13, j + 1, k + 9, Block.stoneBrick.blockID);
		world.setBlock(i + 13, j + 1, k + 10, Block.stoneBrick.blockID);
		world.setBlockAndMetadata(i + 13, j + 2, k + 0, Block.stairCompactCobblestone.blockID, 2);
		world.setBlock(i + 13, j + 2, k + 1, Block.stoneBrick.blockID);
		world.setBlock(i + 13, j + 2, k + 9, Block.stoneBrick.blockID);
		world.setBlockAndMetadata(i + 13, j + 2, k + 10, Block.stairCompactCobblestone.blockID, 3);
		world.setBlockAndMetadata(i + 13, j + 3, k + 0, Block.stairCompactCobblestone.blockID, 2);
		world.setBlock(i + 13, j + 3, k + 1, Block.stoneBrick.blockID);
		world.setBlock(i + 13, j + 3, k + 9, Block.stoneBrick.blockID);
		world.setBlockAndMetadata(i + 13, j + 3, k + 10, Block.stairCompactCobblestone.blockID, 3);
		world.setBlockAndMetadata(i + 13, j + 4, k + 0, Block.stairCompactCobblestone.blockID, 2);
		world.setBlock(i + 13, j + 4, k + 1, Block.stoneBrick.blockID);
		world.setBlock(i + 13, j + 4, k + 9, Block.stoneBrick.blockID);
		world.setBlockAndMetadata(i + 13, j + 4, k + 10, Block.stairCompactCobblestone.blockID, 3);
		world.setBlockAndMetadata(i + 13, j + 5, k + 0, Block.stairCompactCobblestone.blockID, 2);
		world.setBlock(i + 13, j + 5, k + 1, Block.stoneBrick.blockID);
		world.setBlock(i + 13, j + 5, k + 9, Block.stoneBrick.blockID);
		world.setBlockAndMetadata(i + 13, j + 5, k + 10, Block.stairCompactCobblestone.blockID, 3);
		world.setBlockAndMetadata(i + 13, j + 6, k + 0, Block.stairCompactCobblestone.blockID, 2);
		world.setBlock(i + 13, j + 6, k + 1, Block.stoneBrick.blockID);
		world.setBlock(i + 13, j + 6, k + 2, Block.glowStone.blockID);
		world.setBlock(i + 13, j + 6, k + 8, Block.glowStone.blockID);
		world.setBlock(i + 13, j + 6, k + 9, Block.stoneBrick.blockID);
		world.setBlockAndMetadata(i + 13, j + 6, k + 10, Block.stairCompactCobblestone.blockID, 3);
		world.setBlockAndMetadata(i + 13, j + 7, k + 0, Block.stairCompactCobblestone.blockID, 2);
		world.setBlock(i + 13, j + 7, k + 1, Block.stoneBrick.blockID);
		world.setBlock(i + 13, j + 7, k + 2, Block.planks.blockID);
		world.setBlock(i + 13, j + 7, k + 3, Block.planks.blockID);
		world.setBlock(i + 13, j + 7, k + 7, Block.planks.blockID);
		world.setBlock(i + 13, j + 7, k + 8, Block.planks.blockID);
		world.setBlock(i + 13, j + 7, k + 9, Block.cobblestone.blockID);
		world.setBlockAndMetadata(i + 13, j + 7, k + 10, Block.stairCompactCobblestone.blockID, 3);
		world.setBlock(i + 13, j + 8, k + 1, Block.fence.blockID);
		world.setBlock(i + 13, j + 8, k + 2, Block.fence.blockID);
		world.setBlockAndMetadata(i + 13, j + 8, k + 3, Block.stoneBrick.blockID, 2);
		world.setBlockAndMetadata(i + 13, j + 8, k + 7, Block.stoneBrick.blockID, 2);
		world.setBlock(i + 13, j + 8, k + 8, Block.fence.blockID);
		world.setBlock(i + 13, j + 8, k + 9, Block.fence.blockID);
		world.setBlock(i + 13, j + 9, k + 2, Block.fence.blockID);
		world.setBlockAndMetadata(i + 13, j + 9, k + 3, Block.stoneBrick.blockID, 2);
		world.setBlockAndMetadata(i + 13, j + 9, k + 7, Block.stoneBrick.blockID, 2);
		world.setBlock(i + 13, j + 9, k + 8, Block.fence.blockID);
		world.setBlock(i + 13, j + 10, k + 2, Block.fence.blockID);
		world.setBlockAndMetadata(i + 13, j + 10, k + 3, Block.stoneBrick.blockID, 2);
		world.setBlockAndMetadata(i + 13, j + 10, k + 7, Block.stoneBrick.blockID, 2);
		world.setBlock(i + 13, j + 10, k + 8, Block.fence.blockID);
		world.setBlock(i + 13, j + 11, k + 2, Block.fence.blockID);
		world.setBlockAndMetadata(i + 13, j + 11, k + 3, Block.stoneBrick.blockID, 2);
		world.setBlockAndMetadata(i + 13, j + 11, k + 7, Block.stoneBrick.blockID, 2);
		world.setBlock(i + 13, j + 11, k + 8, Block.fence.blockID);
		world.setBlock(i + 13, j + 12, k + 2, Block.fence.blockID);
		world.setBlockAndMetadata(i + 13, j + 12, k + 3, Block.stoneBrick.blockID, 2);
		world.setBlockAndMetadata(i + 13, j + 12, k + 7, Block.stoneBrick.blockID, 2);
		world.setBlock(i + 13, j + 12, k + 8, Block.fence.blockID);
		world.setBlock(i + 13, j + 13, k + 2, Block.fence.blockID);
		world.setBlock(i + 13, j + 13, k + 3, Block.glowStone.blockID);
		world.setBlock(i + 13, j + 13, k + 7, Block.glowStone.blockID);
		world.setBlock(i + 13, j + 13, k + 8, Block.fence.blockID);
		world.setBlock(i + 13, j + 14, k + 2, Block.glass.blockID);
		world.setBlock(i + 13, j + 14, k + 3, Block.blockGold.blockID);
		world.setBlock(i + 13, j + 14, k + 7, Block.blockGold.blockID);
		world.setBlock(i + 13, j + 14, k + 8, Block.glass.blockID);
		world.setBlock(i + 13, j + 15, k + 1, Block.glass.blockID);
		world.setBlock(i + 13, j + 15, k + 2, Block.glass.blockID);
		world.setBlock(i + 13, j + 15, k + 3, Block.blockGold.blockID);
		world.setBlock(i + 13, j + 15, k + 7, Block.blockGold.blockID);
		world.setBlock(i + 13, j + 15, k + 8, Block.glass.blockID);
		world.setBlock(i + 13, j + 15, k + 9, Block.glass.blockID);
		world.setBlock(i + 13, j + 16, k + 1, Block.glass.blockID);
		world.setBlock(i + 13, j + 16, k + 2, Block.blockGold.blockID);
		world.setBlock(i + 13, j + 16, k + 8, Block.blockGold.blockID);
		world.setBlock(i + 13, j + 16, k + 9, Block.glass.blockID);
		world.setBlock(i + 13, j + 17, k + 0, Block.glass.blockID);
		world.setBlock(i + 13, j + 17, k + 1, Block.glass.blockID);
		world.setBlock(i + 13, j + 17, k + 2, Block.planks.blockID);
		world.setBlock(i + 13, j + 17, k + 3, Block.planks.blockID);
		world.setBlock(i + 13, j + 17, k + 4, Block.planks.blockID);
		world.setBlock(i + 13, j + 17, k + 5, Block.planks.blockID);
		world.setBlock(i + 13, j + 17, k + 6, Block.planks.blockID);
		world.setBlock(i + 13, j + 17, k + 7, Block.planks.blockID);
		world.setBlock(i + 13, j + 17, k + 8, Block.planks.blockID);
		world.setBlock(i + 13, j + 17, k + 9, Block.glass.blockID);
		world.setBlock(i + 13, j + 17, k + 10, Block.glass.blockID);
		world.setBlock(i + 13, j + 18, k + 0, Block.blockSteel.blockID);
		world.setBlock(i + 13, j + 18, k + 1, Block.bookShelf.blockID);
		world.setBlockAndMetadata(i + 13, j + 18, k + 2, Block.chest.blockID, 3);
		world.setBlockAndMetadata(i + 13, j + 18, k + 8, Block.chest.blockID, 2);
		world.setBlock(i + 13, j + 18, k + 9, Block.bookShelf.blockID);
		world.setBlock(i + 13, j + 18, k + 10, Block.blockSteel.blockID);
		world.setBlock(i + 13, j + 19, k + 0, Block.glass.blockID);
		world.setBlock(i + 13, j + 19, k + 1, Block.glass.blockID);
		world.setBlock(i + 13, j + 19, k + 9, Block.glass.blockID);
		world.setBlock(i + 13, j + 19, k + 10, Block.glass.blockID);
		world.setBlock(i + 13, j + 20, k + 1, Block.glass.blockID);
		world.setBlock(i + 13, j + 20, k + 9, Block.glass.blockID);
		world.setBlock(i + 13, j + 21, k + 1, Block.glass.blockID);
		world.setBlock(i + 13, j + 21, k + 2, Block.glass.blockID);
		world.setBlock(i + 13, j + 21, k + 8, Block.glass.blockID);
		world.setBlock(i + 13, j + 21, k + 9, Block.glass.blockID);
		world.setBlock(i + 13, j + 22, k + 2, Block.glass.blockID);
		world.setBlock(i + 13, j + 22, k + 3, Block.glass.blockID);
		world.setBlock(i + 13, j + 22, k + 4, Block.glass.blockID);
		world.setBlock(i + 13, j + 22, k + 6, Block.glass.blockID);
		world.setBlock(i + 13, j + 22, k + 7, Block.glass.blockID);
		world.setBlock(i + 13, j + 22, k + 8, Block.glass.blockID);
		world.setBlock(i + 13, j + 23, k + 4, Block.glass.blockID);
		world.setBlock(i + 13, j + 23, k + 5, Block.blockSteel.blockID);
		world.setBlock(i + 13, j + 23, k + 6, Block.glass.blockID);
		world.setBlock(i + 13, j + 24, k + 5, Block.stairCompactPlanks.blockID);
		world.setBlock(i + 14, j + 0, k + 0, Block.cobblestone.blockID);
		world.setBlock(i + 14, j + 0, k + 1, Block.cobblestone.blockID);
		world.setBlock(i + 14, j + 0, k + 2, Block.cobblestone.blockID);
		world.setBlock(i + 14, j + 0, k + 3, Block.cobblestone.blockID);
		world.setBlock(i + 14, j + 0, k + 4, Block.cobblestone.blockID);
		world.setBlock(i + 14, j + 0, k + 5, Block.glowStone.blockID);
		world.setBlock(i + 14, j + 0, k + 6, Block.cobblestone.blockID);
		world.setBlock(i + 14, j + 0, k + 7, Block.cobblestone.blockID);
		world.setBlock(i + 14, j + 0, k + 8, Block.cobblestone.blockID);
		world.setBlock(i + 14, j + 0, k + 9, Block.cobblestone.blockID);
		world.setBlock(i + 14, j + 0, k + 10, Block.cobblestone.blockID);
		world.setBlockAndMetadata(i + 14, j + 1, k + 0, Block.stoneBrick.blockID, 2);
		world.setBlockAndMetadata(i + 14, j + 1, k + 1, Block.stairCompactPlanks.blockID, 1);
		world.setBlockAndMetadata(i + 14, j + 1, k + 2, Block.stoneOvenActive.blockID, 3);
		world.setBlockAndMetadata(i + 14, j + 1, k + 8, Block.stoneOvenActive.blockID, 2);
		world.setBlockAndMetadata(i + 14, j + 1, k + 9, Block.stairCompactPlanks.blockID, 1);
		world.setBlock(i + 14, j + 1, k + 10, Block.stoneBrick.blockID);
		world.setBlockAndMetadata(i + 14, j + 2, k + 1, Block.stairCompactPlanks.blockID, 1);
		world.setBlockAndMetadata(i + 14, j + 2, k + 9, Block.stairCompactPlanks.blockID, 1);
		world.setBlockAndMetadata(i + 14, j + 3, k + 1, Block.stairCompactPlanks.blockID, 1);
		world.setBlockAndMetadata(i + 14, j + 3, k + 9, Block.stairCompactPlanks.blockID, 1);
		world.setBlockAndMetadata(i + 14, j + 4, k + 1, Block.stairCompactPlanks.blockID, 1);
		world.setBlockAndMetadata(i + 14, j + 4, k + 9, Block.stairCompactPlanks.blockID, 1);
		world.setBlockAndMetadata(i + 14, j + 5, k + 1, Block.stairCompactPlanks.blockID, 1);
		world.setBlockAndMetadata(i + 14, j + 5, k + 9, Block.stairCompactPlanks.blockID, 1);
		world.setBlockAndMetadata(i + 14, j + 6, k + 1, Block.stairCompactPlanks.blockID, 1);
		world.setBlock(i + 14, j + 6, k + 2, Block.bookShelf.blockID);
		world.setBlock(i + 14, j + 6, k + 8, Block.bookShelf.blockID);
		world.setBlockAndMetadata(i + 14, j + 6, k + 9, Block.stairCompactPlanks.blockID, 1);
		world.setBlockAndMetadata(i + 14, j + 7, k + 1, Block.stairCompactPlanks.blockID, 1);
		world.setBlock(i + 14, j + 7, k + 2, Block.planks.blockID);
		world.setBlock(i + 14, j + 7, k + 8, Block.planks.blockID);
		world.setBlockAndMetadata(i + 14, j + 7, k + 9, Block.stairCompactPlanks.blockID, 1);
		world.setBlock(i + 14, j + 8, k + 1, Block.fence.blockID);
		world.setBlockAndMetadata(i + 14, j + 8, k + 2, Block.wood.blockID, 1);
		world.setBlockAndMetadata(i + 14, j + 8, k + 8, Block.wood.blockID, 1);
		world.setBlock(i + 14, j + 8, k + 9, Block.fence.blockID);
		world.setBlockAndMetadata(i + 14, j + 9, k + 2, Block.wood.blockID, 1);
		world.setBlockAndMetadata(i + 14, j + 9, k + 8, Block.wood.blockID, 1);
		world.setBlock(i + 14, j + 10, k + 2, Block.brick.blockID);
		world.setBlock(i + 14, j + 10, k + 8, Block.brick.blockID);
		world.setBlockAndMetadata(i + 14, j + 11, k + 2, Block.wood.blockID, 1);
		world.setBlockAndMetadata(i + 14, j + 11, k + 8, Block.wood.blockID, 1);
		world.setBlockAndMetadata(i + 14, j + 12, k + 2, Block.wood.blockID, 1);
		world.setBlockAndMetadata(i + 14, j + 12, k + 8, Block.wood.blockID, 1);
		world.setBlockAndMetadata(i + 14, j + 13, k + 2, Block.stairCompactPlanks.blockID, 2);
		world.setBlockAndMetadata(i + 14, j + 13, k + 8, Block.stairCompactPlanks.blockID, 3);
		world.setBlock(i + 14, j + 14, k + 2, Block.glass.blockID);
		world.setBlock(i + 14, j + 14, k + 8, Block.glass.blockID);
		world.setBlock(i + 14, j + 15, k + 1, Block.glass.blockID);
		world.setBlock(i + 14, j + 15, k + 9, Block.glass.blockID);
		world.setBlock(i + 14, j + 16, k + 0, Block.glass.blockID);
		world.setBlock(i + 14, j + 16, k + 1, Block.glass.blockID);
		world.setBlock(i + 14, j + 16, k + 9, Block.glass.blockID);
		world.setBlock(i + 14, j + 16, k + 10, Block.glass.blockID);
		world.setBlock(i + 14, j + 17, k + 0, Block.glass.blockID);
		world.setBlock(i + 14, j + 17, k + 1, Block.planks.blockID);
		world.setBlock(i + 14, j + 17, k + 2, Block.planks.blockID);
		world.setBlock(i + 14, j + 17, k + 3, Block.planks.blockID);
		world.setBlock(i + 14, j + 17, k + 4, Block.planks.blockID);
		world.setBlock(i + 14, j + 17, k + 5, Block.planks.blockID);
		world.setBlock(i + 14, j + 17, k + 6, Block.planks.blockID);
		world.setBlock(i + 14, j + 17, k + 7, Block.planks.blockID);
		world.setBlock(i + 14, j + 17, k + 8, Block.planks.blockID);
		world.setBlock(i + 14, j + 17, k + 9, Block.planks.blockID);
		world.setBlock(i + 14, j + 17, k + 10, Block.glass.blockID);
		world.setBlock(i + 14, j + 18, k + 0, Block.blockSteel.blockID);
		world.setBlock(i + 14, j + 18, k + 1, Block.bookShelf.blockID);
		world.setBlock(i + 14, j + 18, k + 4, Block.fence.blockID);
		world.setBlock(i + 14, j + 18, k + 5, Block.fence.blockID);
		world.setBlock(i + 14, j + 18, k + 6, Block.fence.blockID);
		world.setBlock(i + 14, j + 18, k + 9, Block.bookShelf.blockID);
		world.setBlock(i + 14, j + 18, k + 10, Block.blockSteel.blockID);
		world.setBlock(i + 14, j + 19, k + 0, Block.glass.blockID);
		world.setBlock(i + 14, j + 19, k + 1, Block.bookShelf.blockID);
		world.setBlock(i + 14, j + 19, k + 9, Block.bookShelf.blockID);
		world.setBlock(i + 14, j + 19, k + 10, Block.glass.blockID);
		world.setBlock(i + 14, j + 20, k + 0, Block.glass.blockID);
		world.setBlock(i + 14, j + 20, k + 1, Block.glass.blockID);
		world.setBlock(i + 14, j + 20, k + 9, Block.glass.blockID);
		world.setBlock(i + 14, j + 20, k + 10, Block.glass.blockID);
		world.setBlock(i + 14, j + 21, k + 1, Block.glass.blockID);
		world.setBlock(i + 14, j + 21, k + 9, Block.glass.blockID);
		world.setBlock(i + 14, j + 22, k + 2, Block.glass.blockID);
		world.setBlock(i + 14, j + 22, k + 3, Block.glass.blockID);
		world.setBlock(i + 14, j + 22, k + 7, Block.glass.blockID);
		world.setBlock(i + 14, j + 22, k + 8, Block.glass.blockID);
		world.setBlock(i + 14, j + 23, k + 3, Block.glass.blockID);
		world.setBlock(i + 14, j + 23, k + 4, Block.glass.blockID);
		world.setBlock(i + 14, j + 23, k + 5, Block.blockSteel.blockID);
		world.setBlock(i + 14, j + 23, k + 6, Block.glass.blockID);
		world.setBlock(i + 14, j + 23, k + 7, Block.glass.blockID);
		world.setBlock(i + 14, j + 24, k + 5, Block.planks.blockID);
		world.setBlock(i + 14, j + 25, k + 5, Block.stairCompactPlanks.blockID);
		world.setBlock(i + 15, j + 0, k + 0, Block.cobblestone.blockID);
		world.setBlock(i + 15, j + 0, k + 1, Block.cobblestone.blockID);
		world.setBlock(i + 15, j + 0, k + 2, Block.cobblestone.blockID);
		world.setBlock(i + 15, j + 0, k + 3, Block.cobblestone.blockID);
		world.setBlock(i + 15, j + 0, k + 4, Block.glowStone.blockID);
		world.setBlock(i + 15, j + 0, k + 5, Block.glowStone.blockID);
		world.setBlock(i + 15, j + 0, k + 6, Block.glowStone.blockID);
		world.setBlock(i + 15, j + 0, k + 7, Block.cobblestone.blockID);
		world.setBlock(i + 15, j + 0, k + 8, Block.cobblestone.blockID);
		world.setBlock(i + 15, j + 0, k + 9, Block.cobblestone.blockID);
		world.setBlock(i + 15, j + 0, k + 10, Block.cobblestone.blockID);
		world.setBlockAndMetadata(i + 15, j + 1, k + 0, Block.stoneBrick.blockID, 2);
		world.setBlockAndMetadata(i + 15, j + 1, k + 1, Block.stoneSingleSlab.blockID, 2);
		world.setBlockAndMetadata(i + 15, j + 1, k + 2, Block.stoneOvenActive.blockID, 3);
		world.setBlockAndMetadata(i + 15, j + 1, k + 8, Block.stoneOvenActive.blockID, 2);
		world.setBlockAndMetadata(i + 15, j + 1, k + 9, Block.stoneSingleSlab.blockID, 2);
		world.setBlock(i + 15, j + 1, k + 10, Block.cobblestone.blockID);
		world.setBlockAndMetadata(i + 15, j + 2, k + 1, Block.stoneSingleSlab.blockID, 2);
		world.setBlockAndMetadata(i + 15, j + 2, k + 9, Block.stoneSingleSlab.blockID, 2);
		world.setBlockAndMetadata(i + 15, j + 3, k + 1, Block.stoneSingleSlab.blockID, 2);
		world.setBlockAndMetadata(i + 15, j + 3, k + 9, Block.stoneSingleSlab.blockID, 2);
		world.setBlockAndMetadata(i + 15, j + 4, k + 1, Block.stoneSingleSlab.blockID, 2);
		world.setBlockAndMetadata(i + 15, j + 4, k + 9, Block.stoneSingleSlab.blockID, 2);
		world.setBlockAndMetadata(i + 15, j + 5, k + 1, Block.stoneSingleSlab.blockID, 2);
		world.setBlockAndMetadata(i + 15, j + 5, k + 9, Block.stoneSingleSlab.blockID, 2);
		world.setBlockAndMetadata(i + 15, j + 6, k + 1, Block.stoneSingleSlab.blockID, 2);
		world.setBlock(i + 15, j + 6, k + 2, Block.bookShelf.blockID);
		world.setBlock(i + 15, j + 6, k + 8, Block.bookShelf.blockID);
		world.setBlockAndMetadata(i + 15, j + 6, k + 9, Block.stoneSingleSlab.blockID, 2);
		world.setBlockAndMetadata(i + 15, j + 7, k + 1, Block.stoneSingleSlab.blockID, 2);
		world.setBlock(i + 15, j + 7, k + 2, Block.planks.blockID);
		world.setBlock(i + 15, j + 7, k + 8, Block.planks.blockID);
		world.setBlockAndMetadata(i + 15, j + 7, k + 9, Block.stoneSingleSlab.blockID, 2);
		world.setBlock(i + 15, j + 8, k + 1, Block.fence.blockID);
		world.setBlock(i + 15, j + 8, k + 2, Block.wood.blockID);
		world.setBlock(i + 15, j + 8, k + 8, Block.wood.blockID);
		world.setBlock(i + 15, j + 8, k + 9, Block.fence.blockID);
		world.setBlock(i + 15, j + 9, k + 2, Block.brick.blockID);
		world.setBlock(i + 15, j + 9, k + 8, Block.brick.blockID);
		world.setBlock(i + 15, j + 10, k + 2, Block.brick.blockID);
		world.setBlock(i + 15, j + 10, k + 8, Block.brick.blockID);
		world.setBlock(i + 15, j + 11, k + 2, Block.brick.blockID);
		world.setBlock(i + 15, j + 11, k + 8, Block.brick.blockID);
		world.setBlock(i + 15, j + 12, k + 2, Block.wood.blockID);
		world.setBlock(i + 15, j + 12, k + 8, Block.wood.blockID);
		world.setBlockAndMetadata(i + 15, j + 13, k + 2, Block.stairCompactPlanks.blockID, 2);
		world.setBlockAndMetadata(i + 15, j + 13, k + 8, Block.stairCompactPlanks.blockID, 3);
		world.setBlock(i + 15, j + 14, k + 2, Block.blockSteel.blockID);
		world.setBlock(i + 15, j + 14, k + 8, Block.blockSteel.blockID);
		world.setBlock(i + 15, j + 15, k + 1, Block.blockSteel.blockID);
		world.setBlock(i + 15, j + 15, k + 9, Block.blockSteel.blockID);
		world.setBlock(i + 15, j + 16, k + 0, Block.blockSteel.blockID);
		world.setBlock(i + 15, j + 16, k + 10, Block.blockSteel.blockID);
		world.setBlock(i + 15, j + 17, k + 0, Block.blockSteel.blockID);
		world.setBlock(i + 15, j + 17, k + 1, Block.planks.blockID);
		world.setBlock(i + 15, j + 17, k + 2, Block.planks.blockID);
		world.setBlock(i + 15, j + 17, k + 3, Block.planks.blockID);
		world.setBlock(i + 15, j + 17, k + 4, Block.planks.blockID);
		world.setBlock(i + 15, j + 17, k + 5, Block.planks.blockID);
		world.setBlock(i + 15, j + 17, k + 6, Block.planks.blockID);
		world.setBlock(i + 15, j + 17, k + 7, Block.planks.blockID);
		world.setBlock(i + 15, j + 17, k + 8, Block.planks.blockID);
		world.setBlock(i + 15, j + 17, k + 9, Block.planks.blockID);
		world.setBlock(i + 15, j + 17, k + 10, Block.blockSteel.blockID);
		world.setBlock(i + 15, j + 18, k + 0, Block.blockSteel.blockID);
		world.setBlock(i + 15, j + 18, k + 1, Block.bookShelf.blockID);
		world.setBlock(i + 15, j + 18, k + 9, Block.bookShelf.blockID);
		world.setBlock(i + 15, j + 18, k + 10, Block.blockSteel.blockID);
		world.setBlock(i + 15, j + 19, k + 0, Block.blockSteel.blockID);
		world.setBlock(i + 15, j + 19, k + 1, Block.bookShelf.blockID);
		world.setBlock(i + 15, j + 19, k + 9, Block.bookShelf.blockID);
		world.setBlock(i + 15, j + 19, k + 10, Block.blockSteel.blockID);
		world.setBlock(i + 15, j + 20, k + 0, Block.blockSteel.blockID);
		world.setBlock(i + 15, j + 20, k + 1, Block.bookShelf.blockID);
		world.setBlock(i + 15, j + 20, k + 9, Block.bookShelf.blockID);
		world.setBlock(i + 15, j + 20, k + 10, Block.blockSteel.blockID);
		world.setBlockAndMetadata(i + 15, j + 21, k + 0, Block.stairCompactPlanks.blockID, 2);
		world.setBlock(i + 15, j + 21, k + 1, Block.blockSteel.blockID);
		world.setBlock(i + 15, j + 21, k + 9, Block.blockSteel.blockID);
		world.setBlockAndMetadata(i + 15, j + 21, k + 10, Block.stairCompactPlanks.blockID, 3);
		world.setBlockAndMetadata(i + 15, j + 22, k + 1, Block.stairCompactPlanks.blockID, 2);
		world.setBlock(i + 15, j + 22, k + 2, Block.blockSteel.blockID);
		world.setBlock(i + 15, j + 22, k + 8, Block.blockSteel.blockID);
		world.setBlockAndMetadata(i + 15, j + 22, k + 9, Block.stairCompactPlanks.blockID, 3);
		world.setBlockAndMetadata(i + 15, j + 23, k + 2, Block.stairCompactPlanks.blockID, 2);
		world.setBlock(i + 15, j + 23, k + 3, Block.blockSteel.blockID);
		world.setBlock(i + 15, j + 23, k + 4, Block.blockSteel.blockID);
		world.setBlock(i + 15, j + 23, k + 5, Block.glowStone.blockID);
		world.setBlock(i + 15, j + 23, k + 6, Block.blockSteel.blockID);
		world.setBlock(i + 15, j + 23, k + 7, Block.blockSteel.blockID);
		world.setBlockAndMetadata(i + 15, j + 23, k + 8, Block.stairCompactPlanks.blockID, 3);
		world.setBlockAndMetadata(i + 15, j + 24, k + 3, Block.stairCompactPlanks.blockID, 2);
		world.setBlock(i + 15, j + 24, k + 4, Block.planks.blockID);
		world.setBlock(i + 15, j + 24, k + 5, Block.planks.blockID);
		world.setBlock(i + 15, j + 24, k + 6, Block.planks.blockID);
		world.setBlockAndMetadata(i + 15, j + 24, k + 7, Block.stairCompactPlanks.blockID, 3);
		world.setBlockAndMetadata(i + 15, j + 25, k + 4, Block.stairCompactPlanks.blockID, 2);
		world.setBlock(i + 15, j + 25, k + 5, Block.planks.blockID);
		world.setBlockAndMetadata(i + 15, j + 25, k + 6, Block.stairCompactPlanks.blockID, 3);
		world.setBlock(i + 15, j + 26, k + 5, Block.planks.blockID);
		world.setBlock(i + 15, j + 27, k + 5, Block.fence.blockID);
		world.setBlock(i + 15, j + 28, k + 5, Block.fence.blockID);
		world.setBlock(i + 15, j + 29, k + 5, Block.fence.blockID);
		world.setBlock(i + 16, j + 0, k + 0, Block.cobblestone.blockID);
		world.setBlock(i + 16, j + 0, k + 1, Block.cobblestone.blockID);
		world.setBlock(i + 16, j + 0, k + 2, Block.cobblestone.blockID);
		world.setBlock(i + 16, j + 0, k + 3, Block.cobblestone.blockID);
		world.setBlock(i + 16, j + 0, k + 4, Block.cobblestone.blockID);
		world.setBlock(i + 16, j + 0, k + 5, Block.glowStone.blockID);
		world.setBlock(i + 16, j + 0, k + 6, Block.cobblestone.blockID);
		world.setBlock(i + 16, j + 0, k + 7, Block.cobblestone.blockID);
		world.setBlock(i + 16, j + 0, k + 8, Block.cobblestone.blockID);
		world.setBlock(i + 16, j + 0, k + 9, Block.cobblestone.blockID);
		world.setBlock(i + 16, j + 0, k + 10, Block.cobblestone.blockID);
		world.setBlockAndMetadata(i + 16, j + 1, k + 0, Block.stoneBrick.blockID, 2);
		world.setBlock(i + 16, j + 1, k + 1, Block.stairCompactPlanks.blockID);
		world.setBlockAndMetadata(i + 16, j + 1, k + 2, Block.stoneOvenActive.blockID, 3);
		world.setBlockAndMetadata(i + 16, j + 1, k + 8, Block.stoneOvenActive.blockID, 2);
		world.setBlock(i + 16, j + 1, k + 9, Block.stairCompactPlanks.blockID);
		world.setBlock(i + 16, j + 1, k + 10, Block.cobblestone.blockID);
		world.setBlock(i + 16, j + 2, k + 1, Block.stairCompactPlanks.blockID);
		world.setBlock(i + 16, j + 2, k + 9, Block.stairCompactPlanks.blockID);
		world.setBlock(i + 16, j + 3, k + 1, Block.stairCompactPlanks.blockID);
		world.setBlock(i + 16, j + 3, k + 9, Block.stairCompactPlanks.blockID);
		world.setBlock(i + 16, j + 4, k + 1, Block.stairCompactPlanks.blockID);
		world.setBlock(i + 16, j + 4, k + 9, Block.stairCompactPlanks.blockID);
		world.setBlock(i + 16, j + 5, k + 1, Block.stairCompactPlanks.blockID);
		world.setBlock(i + 16, j + 5, k + 9, Block.stairCompactPlanks.blockID);
		world.setBlock(i + 16, j + 6, k + 1, Block.stairCompactPlanks.blockID);
		world.setBlock(i + 16, j + 6, k + 2, Block.bookShelf.blockID);
		world.setBlock(i + 16, j + 6, k + 8, Block.bookShelf.blockID);
		world.setBlock(i + 16, j + 6, k + 9, Block.stairCompactPlanks.blockID);
		world.setBlock(i + 16, j + 7, k + 1, Block.stairCompactPlanks.blockID);
		world.setBlock(i + 16, j + 7, k + 2, Block.planks.blockID);
		world.setBlock(i + 16, j + 7, k + 8, Block.planks.blockID);
		world.setBlock(i + 16, j + 7, k + 9, Block.stairCompactPlanks.blockID);
		world.setBlock(i + 16, j + 8, k + 1, Block.fence.blockID);
		world.setBlockAndMetadata(i + 16, j + 8, k + 2, Block.wood.blockID, 1);
		world.setBlockAndMetadata(i + 16, j + 8, k + 8, Block.wood.blockID, 1);
		world.setBlock(i + 16, j + 8, k + 9, Block.fence.blockID);
		world.setBlockAndMetadata(i + 16, j + 9, k + 2, Block.wood.blockID, 1);
		world.setBlockAndMetadata(i + 16, j + 9, k + 8, Block.wood.blockID, 1);
		world.setBlock(i + 16, j + 10, k + 2, Block.brick.blockID);
		world.setBlock(i + 16, j + 10, k + 8, Block.brick.blockID);
		world.setBlockAndMetadata(i + 16, j + 11, k + 2, Block.wood.blockID, 1);
		world.setBlockAndMetadata(i + 16, j + 11, k + 8, Block.wood.blockID, 1);
		world.setBlockAndMetadata(i + 16, j + 12, k + 2, Block.wood.blockID, 1);
		world.setBlockAndMetadata(i + 16, j + 12, k + 8, Block.wood.blockID, 1);
		world.setBlockAndMetadata(i + 16, j + 13, k + 2, Block.stairCompactPlanks.blockID, 2);
		world.setBlockAndMetadata(i + 16, j + 13, k + 8, Block.stairCompactPlanks.blockID, 3);
		world.setBlock(i + 16, j + 14, k + 2, Block.glass.blockID);
		world.setBlock(i + 16, j + 14, k + 8, Block.glass.blockID);
		world.setBlock(i + 16, j + 15, k + 1, Block.glass.blockID);
		world.setBlock(i + 16, j + 15, k + 9, Block.glass.blockID);
		world.setBlock(i + 16, j + 16, k + 0, Block.glass.blockID);
		world.setBlock(i + 16, j + 16, k + 1, Block.glass.blockID);
		world.setBlock(i + 16, j + 16, k + 9, Block.glass.blockID);
		world.setBlock(i + 16, j + 16, k + 10, Block.glass.blockID);
		world.setBlock(i + 16, j + 17, k + 0, Block.glass.blockID);
		world.setBlock(i + 16, j + 17, k + 1, Block.planks.blockID);
		world.setBlock(i + 16, j + 17, k + 2, Block.planks.blockID);
		world.setBlock(i + 16, j + 17, k + 3, Block.planks.blockID);
		world.setBlock(i + 16, j + 17, k + 4, Block.planks.blockID);
		world.setBlock(i + 16, j + 17, k + 5, Block.planks.blockID);
		world.setBlock(i + 16, j + 17, k + 6, Block.planks.blockID);
		world.setBlock(i + 16, j + 17, k + 7, Block.planks.blockID);
		world.setBlock(i + 16, j + 17, k + 8, Block.planks.blockID);
		world.setBlock(i + 16, j + 17, k + 9, Block.planks.blockID);
		world.setBlock(i + 16, j + 17, k + 10, Block.glass.blockID);
		world.setBlock(i + 16, j + 18, k + 0, Block.blockSteel.blockID);
		world.setBlock(i + 16, j + 18, k + 1, Block.bookShelf.blockID);
		world.setBlock(i + 16, j + 18, k + 9, Block.bookShelf.blockID);
		world.setBlock(i + 16, j + 18, k + 10, Block.blockSteel.blockID);
		world.setBlock(i + 16, j + 19, k + 0, Block.glass.blockID);
		world.setBlock(i + 16, j + 19, k + 1, Block.bookShelf.blockID);
		world.setBlock(i + 16, j + 19, k + 9, Block.bookShelf.blockID);
		world.setBlock(i + 16, j + 19, k + 10, Block.glass.blockID);
		world.setBlock(i + 16, j + 20, k + 0, Block.glass.blockID);
		world.setBlock(i + 16, j + 20, k + 9, Block.glass.blockID);
		world.setBlock(i + 16, j + 20, k + 10, Block.glass.blockID);
		world.setBlock(i + 16, j + 21, k + 1, Block.glass.blockID);
		world.setBlock(i + 16, j + 21, k + 9, Block.glass.blockID);
		world.setBlock(i + 16, j + 22, k + 2, Block.glass.blockID);
		world.setBlock(i + 16, j + 22, k + 3, Block.glass.blockID);
		world.setBlock(i + 16, j + 22, k + 7, Block.glass.blockID);
		world.setBlock(i + 16, j + 22, k + 8, Block.glass.blockID);
		world.setBlock(i + 16, j + 23, k + 3, Block.glass.blockID);
		world.setBlock(i + 16, j + 23, k + 4, Block.glass.blockID);
		world.setBlock(i + 16, j + 23, k + 5, Block.blockSteel.blockID);
		world.setBlock(i + 16, j + 23, k + 6, Block.glass.blockID);
		world.setBlock(i + 16, j + 23, k + 7, Block.glass.blockID);
		world.setBlock(i + 16, j + 24, k + 5, Block.planks.blockID);
		world.setBlockAndMetadata(i + 16, j + 25, k + 5, Block.stairCompactPlanks.blockID, 1);
		world.setBlock(i + 17, j + 0, k + 0, Block.cobblestone.blockID);
		world.setBlock(i + 17, j + 0, k + 1, Block.cobblestone.blockID);
		world.setBlock(i + 17, j + 0, k + 2, Block.cobblestone.blockID);
		world.setBlock(i + 17, j + 0, k + 3, Block.cobblestone.blockID);
		world.setBlock(i + 17, j + 0, k + 4, Block.cobblestone.blockID);
		world.setBlock(i + 17, j + 0, k + 5, Block.cobblestone.blockID);
		world.setBlock(i + 17, j + 0, k + 6, Block.cobblestone.blockID);
		world.setBlock(i + 17, j + 0, k + 7, Block.cobblestone.blockID);
		world.setBlock(i + 17, j + 0, k + 8, Block.cobblestone.blockID);
		world.setBlock(i + 17, j + 0, k + 9, Block.cobblestone.blockID);
		world.setBlock(i + 17, j + 0, k + 10, Block.cobblestone.blockID);
		world.setBlockAndMetadata(i + 17, j + 1, k + 0, Block.stoneBrick.blockID, 2);
		world.setBlock(i + 17, j + 1, k + 1, Block.stoneBrick.blockID);
		world.setBlockAndMetadata(i + 17, j + 1, k + 2, Block.stoneOvenActive.blockID, 3);
		world.setBlockAndMetadata(i + 17, j + 1, k + 8, Block.stoneOvenActive.blockID, 2);
		world.setBlock(i + 17, j + 1, k + 9, Block.stoneBrick.blockID);
		world.setBlock(i + 17, j + 1, k + 10, Block.cobblestone.blockID);
		world.setBlockAndMetadata(i + 17, j + 2, k + 0, Block.stairCompactCobblestone.blockID, 2);
		world.setBlock(i + 17, j + 2, k + 1, Block.stoneBrick.blockID);
		world.setBlock(i + 17, j + 2, k + 9, Block.stoneBrick.blockID);
		world.setBlockAndMetadata(i + 17, j + 2, k + 10, Block.stairCompactCobblestone.blockID, 3);
		world.setBlockAndMetadata(i + 17, j + 3, k + 0, Block.stairCompactCobblestone.blockID, 2);
		world.setBlock(i + 17, j + 3, k + 1, Block.stoneBrick.blockID);
		world.setBlock(i + 17, j + 3, k + 9, Block.stoneBrick.blockID);
		world.setBlockAndMetadata(i + 17, j + 3, k + 10, Block.stairCompactCobblestone.blockID, 3);
		world.setBlockAndMetadata(i + 17, j + 4, k + 0, Block.stairCompactCobblestone.blockID, 2);
		world.setBlock(i + 17, j + 4, k + 1, Block.stoneBrick.blockID);
		world.setBlock(i + 17, j + 4, k + 9, Block.stoneBrick.blockID);
		world.setBlockAndMetadata(i + 17, j + 4, k + 10, Block.stairCompactCobblestone.blockID, 3);
		world.setBlockAndMetadata(i + 17, j + 5, k + 0, Block.stairCompactCobblestone.blockID, 2);
		world.setBlock(i + 17, j + 5, k + 1, Block.stoneBrick.blockID);
		world.setBlock(i + 17, j + 5, k + 9, Block.stoneBrick.blockID);
		world.setBlockAndMetadata(i + 17, j + 5, k + 10, Block.stairCompactCobblestone.blockID, 3);
		world.setBlockAndMetadata(i + 17, j + 6, k + 0, Block.stairCompactCobblestone.blockID, 2);
		world.setBlock(i + 17, j + 6, k + 1, Block.stoneBrick.blockID);
		world.setBlock(i + 17, j + 6, k + 2, Block.glowStone.blockID);
		world.setBlock(i + 17, j + 6, k + 8, Block.glowStone.blockID);
		world.setBlock(i + 17, j + 6, k + 9, Block.stoneBrick.blockID);
		world.setBlockAndMetadata(i + 17, j + 6, k + 10, Block.stairCompactCobblestone.blockID, 3);
		world.setBlockAndMetadata(i + 17, j + 7, k + 0, Block.stairCompactCobblestone.blockID, 2);
		world.setBlock(i + 17, j + 7, k + 1, Block.stoneBrick.blockID);
		world.setBlock(i + 17, j + 7, k + 2, Block.planks.blockID);
		world.setBlock(i + 17, j + 7, k + 3, Block.planks.blockID);
		world.setBlock(i + 17, j + 7, k + 7, Block.planks.blockID);
		world.setBlock(i + 17, j + 7, k + 8, Block.planks.blockID);
		world.setBlock(i + 17, j + 7, k + 9, Block.stoneBrick.blockID);
		world.setBlockAndMetadata(i + 17, j + 7, k + 10, Block.stairCompactCobblestone.blockID, 3);
		world.setBlock(i + 17, j + 8, k + 1, Block.fence.blockID);
		world.setBlock(i + 17, j + 8, k + 2, Block.fence.blockID);
		world.setBlockAndMetadata(i + 17, j + 8, k + 3, Block.stoneBrick.blockID, 2);
		world.setBlockAndMetadata(i + 17, j + 8, k + 7, Block.stoneBrick.blockID, 2);
		world.setBlock(i + 17, j + 8, k + 8, Block.fence.blockID);
		world.setBlock(i + 17, j + 8, k + 9, Block.fence.blockID);
		world.setBlock(i + 17, j + 9, k + 2, Block.fence.blockID);
		world.setBlockAndMetadata(i + 17, j + 9, k + 3, Block.stoneBrick.blockID, 2);
		world.setBlockAndMetadata(i + 17, j + 9, k + 7, Block.stoneBrick.blockID, 2);
		world.setBlock(i + 17, j + 9, k + 8, Block.fence.blockID);
		world.setBlock(i + 17, j + 10, k + 2, Block.fence.blockID);
		world.setBlockAndMetadata(i + 17, j + 10, k + 3, Block.stoneBrick.blockID, 2);
		world.setBlockAndMetadata(i + 17, j + 10, k + 7, Block.stoneBrick.blockID, 2);
		world.setBlock(i + 17, j + 10, k + 8, Block.fence.blockID);
		world.setBlock(i + 17, j + 11, k + 2, Block.fence.blockID);
		world.setBlockAndMetadata(i + 17, j + 11, k + 3, Block.stoneBrick.blockID, 2);
		world.setBlockAndMetadata(i + 17, j + 11, k + 7, Block.stoneBrick.blockID, 2);
		world.setBlock(i + 17, j + 11, k + 8, Block.fence.blockID);
		world.setBlock(i + 17, j + 12, k + 2, Block.fence.blockID);
		world.setBlockAndMetadata(i + 17, j + 12, k + 3, Block.stoneBrick.blockID, 2);
		world.setBlockAndMetadata(i + 17, j + 12, k + 7, Block.stoneBrick.blockID, 2);
		world.setBlock(i + 17, j + 12, k + 8, Block.fence.blockID);
		world.setBlock(i + 17, j + 13, k + 2, Block.fence.blockID);
		world.setBlock(i + 17, j + 13, k + 3, Block.glowStone.blockID);
		world.setBlock(i + 17, j + 13, k + 7, Block.glowStone.blockID);
		world.setBlock(i + 17, j + 13, k + 8, Block.fence.blockID);
		world.setBlock(i + 17, j + 14, k + 2, Block.glass.blockID);
		world.setBlock(i + 17, j + 14, k + 3, Block.blockGold.blockID);
		world.setBlock(i + 17, j + 14, k + 7, Block.blockGold.blockID);
		world.setBlock(i + 17, j + 14, k + 8, Block.glass.blockID);
		world.setBlock(i + 17, j + 15, k + 1, Block.glass.blockID);
		world.setBlock(i + 17, j + 15, k + 2, Block.glass.blockID);
		world.setBlock(i + 17, j + 15, k + 3, Block.blockGold.blockID);
		world.setBlock(i + 17, j + 15, k + 7, Block.blockGold.blockID);
		world.setBlock(i + 17, j + 15, k + 8, Block.glass.blockID);
		world.setBlock(i + 17, j + 15, k + 9, Block.glass.blockID);
		world.setBlock(i + 17, j + 16, k + 1, Block.glass.blockID);
		world.setBlock(i + 17, j + 16, k + 2, Block.blockGold.blockID);
		world.setBlock(i + 17, j + 16, k + 8, Block.blockGold.blockID);
		world.setBlock(i + 17, j + 16, k + 9, Block.glass.blockID);
		world.setBlock(i + 17, j + 17, k + 0, Block.glass.blockID);
		world.setBlock(i + 17, j + 17, k + 1, Block.glass.blockID);
		world.setBlock(i + 17, j + 17, k + 2, Block.planks.blockID);
		world.setBlock(i + 17, j + 17, k + 3, Block.planks.blockID);
		world.setBlock(i + 17, j + 17, k + 4, Block.planks.blockID);
		world.setBlock(i + 17, j + 17, k + 6, Block.planks.blockID);
		world.setBlock(i + 17, j + 17, k + 7, Block.planks.blockID);
		world.setBlock(i + 17, j + 17, k + 8, Block.planks.blockID);
		world.setBlock(i + 17, j + 17, k + 9, Block.glass.blockID);
		world.setBlock(i + 17, j + 17, k + 10, Block.glass.blockID);
		world.setBlock(i + 17, j + 18, k + 0, Block.blockSteel.blockID);
		world.setBlock(i + 17, j + 18, k + 1, Block.bookShelf.blockID);
		world.setBlockAndMetadata(i + 17, j + 18, k + 2, Block.chest.blockID, 3);
		world.setBlockAndMetadata(i + 17, j + 18, k + 8, Block.chest.blockID, 2);
		world.setBlock(i + 17, j + 18, k + 9, Block.bookShelf.blockID);
		world.setBlock(i + 17, j + 18, k + 10, Block.blockSteel.blockID);
		world.setBlock(i + 17, j + 19, k + 0, Block.glass.blockID);
		world.setBlock(i + 17, j + 19, k + 1, Block.glass.blockID);
		world.setBlock(i + 17, j + 19, k + 9, Block.glass.blockID);
		world.setBlock(i + 17, j + 19, k + 10, Block.glass.blockID);
		world.setBlock(i + 17, j + 20, k + 1, Block.glass.blockID);
		world.setBlock(i + 17, j + 20, k + 9, Block.glass.blockID);
		world.setBlock(i + 17, j + 21, k + 1, Block.glass.blockID);
		world.setBlock(i + 17, j + 21, k + 2, Block.glass.blockID);
		world.setBlock(i + 17, j + 21, k + 8, Block.glass.blockID);
		world.setBlock(i + 17, j + 21, k + 9, Block.glass.blockID);
		world.setBlock(i + 17, j + 22, k + 2, Block.glass.blockID);
		world.setBlock(i + 17, j + 22, k + 3, Block.glass.blockID);
		world.setBlock(i + 17, j + 22, k + 4, Block.glass.blockID);
		world.setBlock(i + 17, j + 22, k + 6, Block.glass.blockID);
		world.setBlock(i + 17, j + 22, k + 7, Block.glass.blockID);
		world.setBlock(i + 17, j + 22, k + 8, Block.glass.blockID);
		world.setBlock(i + 17, j + 23, k + 4, Block.glass.blockID);
		world.setBlock(i + 17, j + 23, k + 5, Block.blockSteel.blockID);
		world.setBlock(i + 17, j + 23, k + 6, Block.glass.blockID);
		world.setBlockAndMetadata(i + 17, j + 24, k + 5, Block.stairCompactPlanks.blockID, 1);
		world.setBlock(i + 18, j + 0, k + 0, Block.cobblestone.blockID);
		world.setBlock(i + 18, j + 0, k + 1, Block.cobblestone.blockID);
		world.setBlock(i + 18, j + 0, k + 2, Block.cobblestone.blockID);
		world.setBlock(i + 18, j + 0, k + 3, Block.cobblestone.blockID);
		world.setBlock(i + 18, j + 0, k + 4, Block.cobblestone.blockID);
		world.setBlock(i + 18, j + 0, k + 5, Block.cobblestone.blockID);
		world.setBlock(i + 18, j + 0, k + 6, Block.cobblestone.blockID);
		world.setBlock(i + 18, j + 0, k + 7, Block.cobblestone.blockID);
		world.setBlock(i + 18, j + 0, k + 8, Block.cobblestone.blockID);
		world.setBlock(i + 18, j + 0, k + 9, Block.cobblestone.blockID);
		world.setBlock(i + 18, j + 0, k + 10, Block.cobblestone.blockID);
		world.setBlock(i + 18, j + 1, k + 1, Block.stoneBrick.blockID);
		world.setBlock(i + 18, j + 1, k + 2, Block.stoneBrick.blockID);
		world.setBlock(i + 18, j + 1, k + 5, Block.planks.blockID);
		world.setBlock(i + 18, j + 1, k + 8, Block.stoneBrick.blockID);
		world.setBlock(i + 18, j + 1, k + 9, Block.stoneBrick.blockID);
		world.setBlock(i + 18, j + 2, k + 2, Block.stoneBrick.blockID);
		world.setBlock(i + 18, j + 2, k + 5, Block.planks.blockID);
		world.setBlock(i + 18, j + 2, k + 8, Block.stoneBrick.blockID);
		world.setBlock(i + 18, j + 3, k + 2, Block.stoneBrick.blockID);
		world.setBlock(i + 18, j + 3, k + 5, Block.planks.blockID);
		world.setBlock(i + 18, j + 3, k + 8, Block.stoneBrick.blockID);
		world.setBlock(i + 18, j + 4, k + 2, Block.stoneBrick.blockID);
		world.setBlock(i + 18, j + 4, k + 5, Block.planks.blockID);
		world.setBlock(i + 18, j + 4, k + 8, Block.stoneBrick.blockID);
		world.setBlock(i + 18, j + 5, k + 2, Block.stoneBrick.blockID);
		world.setBlock(i + 18, j + 5, k + 5, Block.planks.blockID);
		world.setBlock(i + 18, j + 5, k + 8, Block.stoneBrick.blockID);
		world.setBlock(i + 18, j + 6, k + 2, Block.stoneBrick.blockID);
		world.setBlock(i + 18, j + 6, k + 3, Block.glowStone.blockID);
		world.setBlock(i + 18, j + 6, k + 5, Block.planks.blockID);
		world.setBlock(i + 18, j + 6, k + 7, Block.glowStone.blockID);
		world.setBlock(i + 18, j + 6, k + 8, Block.stoneBrick.blockID);
		world.setBlock(i + 18, j + 7, k + 2, Block.stoneBrick.blockID);
		world.setBlock(i + 18, j + 7, k + 3, Block.planks.blockID);
		world.setBlock(i + 18, j + 7, k + 4, Block.planks.blockID);
		world.setBlock(i + 18, j + 7, k + 5, Block.planks.blockID);
		world.setBlock(i + 18, j + 7, k + 6, Block.planks.blockID);
		world.setBlock(i + 18, j + 7, k + 7, Block.planks.blockID);
		world.setBlock(i + 18, j + 7, k + 8, Block.stoneBrick.blockID);
		world.setBlock(i + 18, j + 8, k + 2, Block.fence.blockID);
		world.setBlock(i + 18, j + 8, k + 3, Block.fence.blockID);
		world.setBlockAndMetadata(i + 18, j + 8, k + 4, Block.wood.blockID, 1);
		world.setBlock(i + 18, j + 8, k + 5, Block.wood.blockID);
		world.setBlockAndMetadata(i + 18, j + 8, k + 6, Block.wood.blockID, 1);
		world.setBlock(i + 18, j + 8, k + 7, Block.fence.blockID);
		world.setBlock(i + 18, j + 8, k + 8, Block.fence.blockID);
		world.setBlock(i + 18, j + 9, k + 2, Block.fence.blockID);
		world.setBlock(i + 18, j + 9, k + 3, Block.fence.blockID);
		world.setBlockAndMetadata(i + 18, j + 9, k + 4, Block.wood.blockID, 1);
		world.setBlock(i + 18, j + 9, k + 5, Block.brick.blockID);
		world.setBlockAndMetadata(i + 18, j + 9, k + 6, Block.wood.blockID, 1);
		world.setBlock(i + 18, j + 9, k + 7, Block.fence.blockID);
		world.setBlock(i + 18, j + 9, k + 8, Block.fence.blockID);
		world.setBlock(i + 18, j + 10, k + 2, Block.fence.blockID);
		world.setBlock(i + 18, j + 10, k + 3, Block.fence.blockID);
		world.setBlock(i + 18, j + 10, k + 4, Block.brick.blockID);
		world.setBlock(i + 18, j + 10, k + 5, Block.brick.blockID);
		world.setBlock(i + 18, j + 10, k + 6, Block.brick.blockID);
		world.setBlock(i + 18, j + 10, k + 7, Block.fence.blockID);
		world.setBlock(i + 18, j + 10, k + 8, Block.fence.blockID);
		world.setBlock(i + 18, j + 11, k + 2, Block.fence.blockID);
		world.setBlock(i + 18, j + 11, k + 3, Block.fence.blockID);
		world.setBlockAndMetadata(i + 18, j + 11, k + 4, Block.wood.blockID, 1);
		world.setBlock(i + 18, j + 11, k + 5, Block.brick.blockID);
		world.setBlockAndMetadata(i + 18, j + 11, k + 6, Block.wood.blockID, 1);
		world.setBlock(i + 18, j + 11, k + 7, Block.fence.blockID);
		world.setBlock(i + 18, j + 11, k + 8, Block.fence.blockID);
		world.setBlock(i + 18, j + 12, k + 2, Block.fence.blockID);
		world.setBlock(i + 18, j + 12, k + 3, Block.fence.blockID);
		world.setBlockAndMetadata(i + 18, j + 12, k + 4, Block.wood.blockID, 1);
		world.setBlock(i + 18, j + 12, k + 5, Block.wood.blockID);
		world.setBlockAndMetadata(i + 18, j + 12, k + 6, Block.wood.blockID, 1);
		world.setBlock(i + 18, j + 12, k + 7, Block.fence.blockID);
		world.setBlock(i + 18, j + 12, k + 8, Block.fence.blockID);
		world.setBlock(i + 18, j + 13, k + 2, Block.fence.blockID);
		world.setBlock(i + 18, j + 13, k + 3, Block.fence.blockID);
		world.setBlockAndMetadata(i + 18, j + 13, k + 4, Block.stairCompactPlanks.blockID, 1);
		world.setBlock(i + 18, j + 13, k + 5, Block.planks.blockID);
		world.setBlockAndMetadata(i + 18, j + 13, k + 6, Block.stairCompactPlanks.blockID, 1);
		world.setBlock(i + 18, j + 13, k + 7, Block.fence.blockID);
		world.setBlock(i + 18, j + 13, k + 8, Block.fence.blockID);
		world.setBlock(i + 18, j + 14, k + 2, Block.fence.blockID);
		world.setBlock(i + 18, j + 14, k + 3, Block.glass.blockID);
		world.setBlock(i + 18, j + 14, k + 4, Block.glass.blockID);
		world.setBlock(i + 18, j + 14, k + 5, Block.blockSteel.blockID);
		world.setBlock(i + 18, j + 14, k + 6, Block.glass.blockID);
		world.setBlock(i + 18, j + 14, k + 7, Block.glass.blockID);
		world.setBlock(i + 18, j + 14, k + 8, Block.fence.blockID);
		world.setBlock(i + 18, j + 15, k + 2, Block.glass.blockID);
		world.setBlock(i + 18, j + 15, k + 3, Block.glass.blockID);
		world.setBlock(i + 18, j + 15, k + 5, Block.planks.blockID);
		world.setBlock(i + 18, j + 15, k + 7, Block.glass.blockID);
		world.setBlock(i + 18, j + 15, k + 8, Block.glass.blockID);
		world.setBlock(i + 18, j + 16, k + 1, Block.glass.blockID);
		world.setBlock(i + 18, j + 16, k + 2, Block.glass.blockID);
		world.setBlock(i + 18, j + 16, k + 3, Block.blockGold.blockID);
		world.setBlock(i + 18, j + 16, k + 5, Block.planks.blockID);
		world.setBlock(i + 18, j + 16, k + 7, Block.blockGold.blockID);
		world.setBlock(i + 18, j + 16, k + 8, Block.glass.blockID);
		world.setBlock(i + 18, j + 16, k + 9, Block.glass.blockID);
		world.setBlock(i + 18, j + 17, k + 1, Block.glass.blockID);
		world.setBlock(i + 18, j + 17, k + 2, Block.planks.blockID);
		world.setBlock(i + 18, j + 17, k + 3, Block.planks.blockID);
		world.setBlock(i + 18, j + 17, k + 4, Block.planks.blockID);
		world.setBlock(i + 18, j + 17, k + 5, Block.planks.blockID);
		world.setBlock(i + 18, j + 17, k + 6, Block.planks.blockID);
		world.setBlock(i + 18, j + 17, k + 7, Block.planks.blockID);
		world.setBlock(i + 18, j + 17, k + 8, Block.planks.blockID);
		world.setBlock(i + 18, j + 17, k + 9, Block.glass.blockID);
		world.setBlock(i + 18, j + 18, k + 1, Block.blockSteel.blockID);
		world.setBlockAndMetadata(i + 18, j + 18, k + 2, Block.chest.blockID, 3);
		world.setBlockAndMetadata(i + 18, j + 18, k + 8, Block.chest.blockID, 2);
		world.setBlock(i + 18, j + 18, k + 9, Block.blockSteel.blockID);
		world.setBlock(i + 18, j + 19, k + 1, Block.glass.blockID);
		world.setBlock(i + 18, j + 19, k + 9, Block.glass.blockID);
		world.setBlock(i + 18, j + 20, k + 1, Block.glass.blockID);
		world.setBlock(i + 18, j + 20, k + 2, Block.glass.blockID);
		world.setBlock(i + 18, j + 20, k + 8, Block.glass.blockID);
		world.setBlock(i + 18, j + 20, k + 9, Block.glass.blockID);
		world.setBlock(i + 18, j + 21, k + 2, Block.glass.blockID);
		world.setBlock(i + 18, j + 21, k + 3, Block.glass.blockID);
		world.setBlock(i + 18, j + 21, k + 7, Block.glass.blockID);
		world.setBlock(i + 18, j + 21, k + 8, Block.glass.blockID);
		world.setBlock(i + 18, j + 22, k + 3, Block.glass.blockID);
		world.setBlock(i + 18, j + 22, k + 4, Block.glass.blockID);
		world.setBlock(i + 18, j + 22, k + 5, Block.blockSteel.blockID);
		world.setBlock(i + 18, j + 22, k + 6, Block.glass.blockID);
		world.setBlock(i + 18, j + 22, k + 7, Block.glass.blockID);
		world.setBlockAndMetadata(i + 18, j + 23, k + 5, Block.stairCompactPlanks.blockID, 1);
		world.setBlock(i + 19, j + 0, k + 0, Block.cobblestone.blockID);
		world.setBlock(i + 19, j + 0, k + 1, Block.cobblestone.blockID);
		world.setBlock(i + 19, j + 0, k + 2, Block.cobblestone.blockID);
		world.setBlock(i + 19, j + 0, k + 3, Block.cobblestone.blockID);
		world.setBlock(i + 19, j + 0, k + 4, Block.cobblestone.blockID);
		world.setBlock(i + 19, j + 0, k + 5, Block.cobblestone.blockID);
		world.setBlock(i + 19, j + 0, k + 6, Block.cobblestone.blockID);
		world.setBlock(i + 19, j + 0, k + 7, Block.cobblestone.blockID);
		world.setBlock(i + 19, j + 0, k + 8, Block.cobblestone.blockID);
		world.setBlock(i + 19, j + 0, k + 9, Block.cobblestone.blockID);
		world.setBlock(i + 19, j + 0, k + 10, Block.cobblestone.blockID);
		world.setBlock(i + 19, j + 1, k + 2, Block.stoneBrick.blockID);
		world.setBlock(i + 19, j + 1, k + 3, Block.stoneBrick.blockID);
		world.setBlockAndMetadata(i + 19, j + 1, k + 4, Block.stairCompactPlanks.blockID, 3);
		world.setBlockAndMetadata(i + 19, j + 1, k + 5, Block.stoneDoubleSlab.blockID, 2);
		world.setBlockAndMetadata(i + 19, j + 1, k + 6, Block.stairCompactPlanks.blockID, 2);
		world.setBlock(i + 19, j + 1, k + 7, Block.stoneBrick.blockID);
		world.setBlockAndMetadata(i + 19, j + 1, k + 8, Block.stoneBrick.blockID, 2);
		world.setBlock(i + 19, j + 2, k + 3, Block.stoneBrick.blockID);
		world.setBlockAndMetadata(i + 19, j + 2, k + 4, Block.stairCompactPlanks.blockID, 3);
		world.setBlockAndMetadata(i + 19, j + 2, k + 5, Block.stoneSingleSlab.blockID, 2);
		world.setBlockAndMetadata(i + 19, j + 2, k + 6, Block.stairCompactPlanks.blockID, 2);
		world.setBlock(i + 19, j + 2, k + 7, Block.stoneBrick.blockID);
		world.setBlock(i + 19, j + 3, k + 3, Block.stoneBrick.blockID);
		world.setBlockAndMetadata(i + 19, j + 3, k + 4, Block.stairCompactPlanks.blockID, 3);
		world.setBlockAndMetadata(i + 19, j + 3, k + 5, Block.stoneSingleSlab.blockID, 2);
		world.setBlockAndMetadata(i + 19, j + 3, k + 6, Block.stairCompactPlanks.blockID, 2);
		world.setBlock(i + 19, j + 3, k + 7, Block.stoneBrick.blockID);
		world.setBlock(i + 19, j + 4, k + 3, Block.stoneBrick.blockID);
		world.setBlockAndMetadata(i + 19, j + 4, k + 4, Block.stairCompactPlanks.blockID, 3);
		world.setBlockAndMetadata(i + 19, j + 4, k + 5, Block.stoneSingleSlab.blockID, 2);
		world.setBlockAndMetadata(i + 19, j + 4, k + 6, Block.stairCompactPlanks.blockID, 2);
		world.setBlock(i + 19, j + 4, k + 7, Block.stoneBrick.blockID);
		world.setBlock(i + 19, j + 5, k + 3, Block.stoneBrick.blockID);
		world.setBlockAndMetadata(i + 19, j + 5, k + 4, Block.stairCompactPlanks.blockID, 3);
		world.setBlockAndMetadata(i + 19, j + 5, k + 5, Block.stoneSingleSlab.blockID, 2);
		world.setBlockAndMetadata(i + 19, j + 5, k + 6, Block.stairCompactPlanks.blockID, 2);
		world.setBlock(i + 19, j + 5, k + 7, Block.stoneBrick.blockID);
		world.setBlock(i + 19, j + 6, k + 3, Block.stoneBrick.blockID);
		world.setBlockAndMetadata(i + 19, j + 6, k + 4, Block.stairCompactPlanks.blockID, 3);
		world.setBlockAndMetadata(i + 19, j + 6, k + 5, Block.stoneSingleSlab.blockID, 2);
		world.setBlockAndMetadata(i + 19, j + 6, k + 6, Block.stairCompactPlanks.blockID, 2);
		world.setBlock(i + 19, j + 6, k + 7, Block.stoneBrick.blockID);
		world.setBlock(i + 19, j + 7, k + 3, Block.stoneBrick.blockID);
		world.setBlockAndMetadata(i + 19, j + 7, k + 4, Block.stairCompactPlanks.blockID, 3);
		world.setBlockAndMetadata(i + 19, j + 7, k + 5, Block.stoneSingleSlab.blockID, 2);
		world.setBlockAndMetadata(i + 19, j + 7, k + 6, Block.stairCompactPlanks.blockID, 2);
		world.setBlock(i + 19, j + 7, k + 7, Block.stoneBrick.blockID);
		world.setBlock(i + 19, j + 8, k + 3, Block.fence.blockID);
		world.setBlock(i + 19, j + 8, k + 4, Block.fence.blockID);
		world.setBlock(i + 19, j + 8, k + 5, Block.fence.blockID);
		world.setBlock(i + 19, j + 8, k + 6, Block.fence.blockID);
		world.setBlock(i + 19, j + 8, k + 7, Block.fence.blockID);
		world.setBlock(i + 19, j + 15, k + 3, Block.glass.blockID);
		world.setBlock(i + 19, j + 15, k + 4, Block.glass.blockID);
		world.setBlock(i + 19, j + 15, k + 5, Block.blockSteel.blockID);
		world.setBlock(i + 19, j + 15, k + 6, Block.glass.blockID);
		world.setBlock(i + 19, j + 15, k + 7, Block.glass.blockID);
		world.setBlock(i + 19, j + 16, k + 2, Block.glass.blockID);
		world.setBlock(i + 19, j + 16, k + 3, Block.glass.blockID);
		world.setBlock(i + 19, j + 16, k + 4, Block.glass.blockID);
		world.setBlock(i + 19, j + 16, k + 6, Block.glass.blockID);
		world.setBlock(i + 19, j + 16, k + 7, Block.glass.blockID);
		world.setBlock(i + 19, j + 16, k + 8, Block.glass.blockID);
		world.setBlock(i + 19, j + 17, k + 2, Block.glass.blockID);
		world.setBlock(i + 19, j + 17, k + 3, Block.glass.blockID);
		world.setBlock(i + 19, j + 17, k + 4, Block.planks.blockID);
		world.setBlock(i + 19, j + 17, k + 5, Block.planks.blockID);
		world.setBlock(i + 19, j + 17, k + 6, Block.planks.blockID);
		world.setBlock(i + 19, j + 17, k + 7, Block.glass.blockID);
		world.setBlock(i + 19, j + 17, k + 8, Block.glass.blockID);
		world.setBlock(i + 19, j + 18, k + 2, Block.blockSteel.blockID);
		world.setBlock(i + 19, j + 18, k + 3, Block.bookShelf.blockID);
		world.setBlock(i + 19, j + 18, k + 4, Block.bookShelf.blockID);
		world.setBlock(i + 19, j + 18, k + 5, Block.bookShelf.blockID);
		world.setBlock(i + 19, j + 18, k + 6, Block.bookShelf.blockID);
		world.setBlock(i + 19, j + 18, k + 7, Block.bookShelf.blockID);
		world.setBlock(i + 19, j + 18, k + 8, Block.blockSteel.blockID);
		world.setBlock(i + 19, j + 19, k + 2, Block.glass.blockID);
		world.setBlock(i + 19, j + 19, k + 3, Block.glass.blockID);
		world.setBlock(i + 19, j + 19, k + 4, Block.bookShelf.blockID);
		world.setBlock(i + 19, j + 19, k + 5, Block.bookShelf.blockID);
		world.setBlock(i + 19, j + 19, k + 6, Block.bookShelf.blockID);
		world.setBlock(i + 19, j + 19, k + 7, Block.glass.blockID);
		world.setBlock(i + 19, j + 19, k + 8, Block.glass.blockID);
		world.setBlock(i + 19, j + 20, k + 2, Block.glass.blockID);
		world.setBlock(i + 19, j + 20, k + 3, Block.glass.blockID);
		world.setBlock(i + 19, j + 20, k + 4, Block.glass.blockID);
		world.setBlock(i + 19, j + 20, k + 5, Block.bookShelf.blockID);
		world.setBlock(i + 19, j + 20, k + 6, Block.glass.blockID);
		world.setBlock(i + 19, j + 20, k + 7, Block.glass.blockID);
		world.setBlock(i + 19, j + 20, k + 8, Block.glass.blockID);
		world.setBlock(i + 19, j + 21, k + 3, Block.glass.blockID);
		world.setBlock(i + 19, j + 21, k + 4, Block.glass.blockID);
		world.setBlock(i + 19, j + 21, k + 5, Block.blockSteel.blockID);
		world.setBlock(i + 19, j + 21, k + 6, Block.glass.blockID);
		world.setBlock(i + 19, j + 21, k + 7, Block.glass.blockID);
		world.setBlockAndMetadata(i + 19, j + 22, k + 5, Block.stairCompactPlanks.blockID, 1);
		world.setBlock(i + 20, j + 0, k + 0, Block.cobblestone.blockID);
		world.setBlock(i + 20, j + 0, k + 1, Block.cobblestone.blockID);
		world.setBlock(i + 20, j + 0, k + 2, Block.cobblestone.blockID);
		world.setBlock(i + 20, j + 0, k + 3, Block.cobblestone.blockID);
		world.setBlock(i + 20, j + 0, k + 4, Block.cobblestone.blockID);
		world.setBlock(i + 20, j + 0, k + 5, Block.cobblestone.blockID);
		world.setBlock(i + 20, j + 0, k + 6, Block.cobblestone.blockID);
		world.setBlock(i + 20, j + 0, k + 7, Block.cobblestone.blockID);
		world.setBlock(i + 20, j + 0, k + 8, Block.cobblestone.blockID);
		world.setBlock(i + 20, j + 0, k + 9, Block.cobblestone.blockID);
		world.setBlock(i + 20, j + 0, k + 10, Block.cobblestone.blockID);
		world.setBlock(i + 20, j + 1, k + 3, Block.cobblestone.blockID);
		world.setBlock(i + 20, j + 1, k + 4, Block.cobblestone.blockID);
		world.setBlockAndMetadata(i + 20, j + 1, k + 5, Block.stoneBrick.blockID, 1);
		world.setBlockAndMetadata(i + 20, j + 1, k + 6, Block.stoneBrick.blockID, 1);
		world.setBlockAndMetadata(i + 20, j + 1, k + 7, Block.stoneBrick.blockID, 1);
		world.setBlockAndMetadata(i + 20, j + 2, k + 3, Block.stairCompactCobblestone.blockID, 1);
		world.setBlockAndMetadata(i + 20, j + 2, k + 7, Block.stairCompactCobblestone.blockID, 1);
		world.setBlockAndMetadata(i + 20, j + 3, k + 3, Block.stairCompactCobblestone.blockID, 1);
		world.setBlockAndMetadata(i + 20, j + 3, k + 7, Block.stairCompactCobblestone.blockID, 1);
		world.setBlockAndMetadata(i + 20, j + 4, k + 3, Block.stairCompactCobblestone.blockID, 1);
		world.setBlockAndMetadata(i + 20, j + 4, k + 7, Block.stairCompactCobblestone.blockID, 1);
		world.setBlockAndMetadata(i + 20, j + 5, k + 3, Block.stairCompactCobblestone.blockID, 1);
		world.setBlockAndMetadata(i + 20, j + 5, k + 7, Block.stairCompactCobblestone.blockID, 1);
		world.setBlockAndMetadata(i + 20, j + 6, k + 3, Block.stairCompactCobblestone.blockID, 1);
		world.setBlockAndMetadata(i + 20, j + 6, k + 7, Block.stairCompactCobblestone.blockID, 1);
		world.setBlockAndMetadata(i + 20, j + 7, k + 3, Block.stairCompactCobblestone.blockID, 1);
		world.setBlockAndMetadata(i + 20, j + 7, k + 7, Block.stairCompactCobblestone.blockID, 1);
		world.setBlock(i + 20, j + 16, k + 4, Block.glass.blockID);
		world.setBlock(i + 20, j + 16, k + 5, Block.blockSteel.blockID);
		world.setBlock(i + 20, j + 16, k + 6, Block.glass.blockID);
		world.setBlock(i + 20, j + 17, k + 3, Block.glass.blockID);
		world.setBlock(i + 20, j + 17, k + 4, Block.glass.blockID);
		world.setBlock(i + 20, j + 17, k + 5, Block.blockSteel.blockID);
		world.setBlock(i + 20, j + 17, k + 6, Block.glass.blockID);
		world.setBlock(i + 20, j + 17, k + 7, Block.glass.blockID);
		world.setBlock(i + 20, j + 18, k + 3, Block.blockSteel.blockID);
		world.setBlock(i + 20, j + 18, k + 4, Block.blockSteel.blockID);
		world.setBlock(i + 20, j + 18, k + 5, Block.blockSteel.blockID);
		world.setBlock(i + 20, j + 18, k + 6, Block.blockSteel.blockID);
		world.setBlock(i + 20, j + 18, k + 7, Block.blockSteel.blockID);
		world.setBlock(i + 20, j + 19, k + 3, Block.glass.blockID);
		world.setBlock(i + 20, j + 19, k + 4, Block.glass.blockID);
		world.setBlock(i + 20, j + 19, k + 5, Block.blockSteel.blockID);
		world.setBlock(i + 20, j + 19, k + 6, Block.glass.blockID);
		world.setBlock(i + 20, j + 19, k + 7, Block.glass.blockID);
		world.setBlock(i + 20, j + 20, k + 4, Block.glass.blockID);
		world.setBlock(i + 20, j + 20, k + 5, Block.blockSteel.blockID);
		world.setBlock(i + 20, j + 20, k + 6, Block.glass.blockID);
		EntityKnux14 var11 = new EntityKnux14(world);

		 var11.setLocationAndAngles((double)i + 17 + 0.5D, (double)j + 2, (double)k + 4 + 0.5D, 0.0F, 0.0F);
        world.spawnEntityInWorld(var11);
   
		world.setBlockAndMetadata(i + 20, j + 21, k + 5, Block.stairCompactPlanks.blockID, 1);
		world.setBlockAndMetadataWithNotify(i + 3, j + 2, k + 3, Block.signPost.blockID, 3);
		world.setBlockWithNotify(i + 14, j + 19, k + 4, Block.pressurePlatePlanks.blockID);
		world.setBlockWithNotify(i + 14, j + 19, k + 5, Block.pressurePlatePlanks.blockID);
		world.setBlockWithNotify(i + 14, j + 19, k + 6, Block.pressurePlatePlanks.blockID);
		world.setBlockAndMetadataWithNotify(i + 17, j + 1, k + 5, Block.ladder.blockID, 4);
		world.setBlockAndMetadataWithNotify(i + 17, j + 2, k + 5, Block.ladder.blockID, 4);
		world.setBlockAndMetadataWithNotify(i + 17, j + 3, k + 5, Block.ladder.blockID, 4);
		world.setBlockAndMetadataWithNotify(i + 17, j + 4, k + 5, Block.ladder.blockID, 4);
		world.setBlockAndMetadataWithNotify(i + 17, j + 5, k + 5, Block.ladder.blockID, 4);
		world.setBlockAndMetadataWithNotify(i + 17, j + 6, k + 5, Block.ladder.blockID, 4);
		world.setBlockAndMetadataWithNotify(i + 17, j + 7, k + 5, Block.ladder.blockID, 4);
		world.setBlockAndMetadataWithNotify(i + 17, j + 8, k + 5, Block.ladder.blockID, 4);
		world.setBlockAndMetadataWithNotify(i + 17, j + 9, k + 5, Block.ladder.blockID, 4);
		world.setBlockAndMetadataWithNotify(i + 17, j + 10, k + 5, Block.ladder.blockID, 4);
		world.setBlockAndMetadataWithNotify(i + 17, j + 11, k + 5, Block.ladder.blockID, 4);
		world.setBlockAndMetadataWithNotify(i + 17, j + 12, k + 5, Block.ladder.blockID, 4);
		world.setBlockAndMetadataWithNotify(i + 17, j + 13, k + 5, Block.ladder.blockID, 4);
		world.setBlockAndMetadataWithNotify(i + 17, j + 14, k + 5, Block.ladder.blockID, 4);
		world.setBlockAndMetadataWithNotify(i + 17, j + 15, k + 5, Block.ladder.blockID, 4);
		world.setBlockAndMetadataWithNotify(i + 17, j + 16, k + 5, Block.ladder.blockID, 4);
		world.setBlockAndMetadataWithNotify(i + 17, j + 17, k + 5, Block.ladder.blockID, 4);

		return true;
	}
}